<mujoco model="go2w_piper">
  <compiler angle="radian" meshdir="assets" autolimits="true" />

  <option cone="elliptic" impratio="100" />

  <default>
    <default class="go2w">
      <geom friction="0.4" margin="0.001" condim="1" />
      <joint axis="0 1 0" damping="0.1" armature="0.01" frictionloss="0.2" />
      <motor ctrlrange="-23.7 23.7" />
      <default class="abduction">
        <joint axis="1 0 0" range="-1.0472 1.0472" />
      </default>
      <default class="hip">
        <default class="front_hip">
          <joint range="-1.5708 3.4907" />
        </default>
        <default class="back_hip">
          <joint range="-0.5236 4.5379" />
        </default>
      </default>
      <default class="knee">
        <joint range="-2.7227 -0.83776" />
        <motor ctrlrange="-45.43 45.43" />
      </default>
      <default class="visual">
        <geom type="mesh" contype="0" conaffinity="0" group="2" />
      </default>
      <default class="collision">
        <geom group="3" />
        <default class="foot">
          <geom size="0.022" pos="-0.002 0 -0.2264" priority="1" condim="6"
            friction="0.8 0.02 0.01" />
        </default>
      </default>
    </default>
  </default>

  <asset>
    <material name="metal" rgba=".9 .95 .95 1" />
    <material name="black" rgba="0 0 0 1" />
    <material name="white" rgba="1 1 1 1" />
    <material name="gray" rgba="0.671705 0.692426 0.774270 1" />
    <material specular="0.5" shininess="0.25" name="linkgray" rgba="0.82 0.82 0.82 1"/>

    <mesh file="go2w/base_0.obj" />
    <mesh file="go2w/base_1.obj" />
    <mesh file="go2w/base_2.obj" />
    <mesh file="go2w/base_3.obj" />
    <mesh file="go2w/base_4.obj" />
    <mesh file="go2w/hip_0.obj" />
    <mesh file="go2w/hip_1.obj" />
    <mesh file="go2w/thigh_0.obj" />
    <mesh file="go2w/thigh_1.obj" />
    <mesh file="go2w/thigh_mirror_0.obj" />
    <mesh file="go2w/thigh_mirror_1.obj" />
    <mesh file="go2w/calf_mirror_0.obj" />
    <mesh file="go2w/calf_mirror_1.obj" />
    <mesh file="go2w/calf.stl" />
    <mesh file="go2w/calf_mirror.stl" />
    <mesh file="go2w/foot.obj" />
    <mesh file="go2w/wheel.stl" />

    <mesh name="arm_base" file="piper/arm_base.STL"/>
    <mesh name="link1" file="piper/rotate_link.STL"/>
    <mesh name="link2" file="piper/lower_arm_link.STL"/>
    <mesh name="link3" file="piper/upper_arm_link.STL"/>
    <mesh name="link4" file="piper/wrist1_link.STL"/>
    <mesh name="link5" file="piper/wrist2_link.STL"/>
    <mesh name="link6" file="piper/link6.STL"/>
    <mesh name="link7" file="piper/link7.STL"/>
    <mesh name="link8" file="piper/link8.STL"/>
  </asset>

  <worldbody>
    <body name="base_link" pos="0 0 0.6" childclass="go2w">
      <inertial pos="0.021112 0 -0.005366" quat="-0.000543471 0.713435 -0.00173769 0.700719"
        mass="6.921"
        diaginertia="0.107027 0.0980771 0.0244531" />
      <freejoint />
      <geom mesh="base_0" material="black" class="visual" />
      <geom mesh="base_1" material="black" class="visual" />
      <geom mesh="base_2" material="black" class="visual" />
      <geom mesh="base_3" material="white" class="visual" />
      <geom mesh="base_4" material="gray" class="visual" />
      <geom size="0.1881 0.04675 0.057" type="box" class="collision" />
      <geom size="0.05 0.045" pos="0.285 0 0.01" type="cylinder" class="collision" />
      <geom size="0.047" pos="0.293 0 -0.06" class="collision" />
      <site name="imu" pos="-0.02557 0 0.04232" />
      <body name="FL_hip" pos="0.1934 0.0465 0">
        <inertial pos="-0.0054 0.00194 -0.000105" quat="0.497014 0.499245 0.505462 0.498237"
          mass="0.678"
          diaginertia="0.00088403 0.000596003 0.000479967" />
        <joint name="FL_hip_joint" class="abduction" />
        <geom mesh="hip_0" material="metal" class="visual" />
        <geom mesh="hip_1" material="gray" class="visual" />
        <geom size="0.046 0.02" pos="0 0.08 0" quat="1 1 0 0" type="cylinder" class="collision" />
        <body name="FL_thigh" pos="0 0.0955 0">
          <inertial pos="-0.00374 -0.0223 -0.0327" quat="0.829533 0.0847635 -0.0200632 0.551623"
            mass="1.152"
            diaginertia="0.00594973 0.00584149 0.000878787" />
          <joint name="FL_thigh_joint" class="front_hip" />
          <geom mesh="thigh_0" material="metal" class="visual" />
          <geom mesh="thigh_1" material="gray" class="visual" />
          <geom size="0.1065 0.01225 0.017" pos="0 0 -0.1065" quat="0.707107 0 0.707107 0"
            type="box" class="collision" />
          <body name="FL_calf" pos="0 0 -0.213">
            <inertial pos="0.00629595 -0.000622121 -0.141417"
              quat="0.710672 0.00154099 -0.00450087 0.703508"
              mass="0.241352" diaginertia="0.0014901 0.00146356 5.31397e-05" />
            <joint name="FL_calf_joint" class="knee" />
            <geom mesh="calf" material="gray" class="visual" />
            <geom size="0.012 0.06" pos="0.008 0 -0.06" quat="0.994493 0 -0.104807 0"
              type="cylinder" class="collision" />
            <geom size="0.011 0.0325" pos="0.02 0 -0.148" quat="0.999688 0 0.0249974 0"
              type="cylinder" class="collision" />

            <body name="FL_wheel_link" pos="0 0 -0.2264">
              <inertial pos="-0.0 0.04 -0.0"
                quat="0.661419 0.248219 0.250051 0.662108" mass="0.98"
                diaginertia="0.003 0.0016 0.0016" />
              <joint name="FL_wheel_joint" pos="0 0 0" axis="0 1 0" />
              <geom type="mesh" rgba="0.15 0.15 0.15 1" mesh="wheel" pos="0 0.0 0"
                quat="0.0 1.0 0.0 0.0" />
              <geom pos="0 0.0 0" quat="0.0 1.0 0.0 0.0" type="mesh" mesh="wheel" class="foot" />
            </body>

          </body>
        </body>
      </body>
      <body name="FR_hip" pos="0.1934 -0.0465 0">
        <inertial pos="-0.0054 -0.00194 -0.000105" quat="0.498237 0.505462 0.499245 0.497014"
          mass="0.678"
          diaginertia="0.00088403 0.000596003 0.000479967" />
        <joint name="FR_hip_joint" class="abduction" />
        <geom mesh="hip_0" material="metal" class="visual" quat="4.63268e-05 1 0 0" />
        <geom mesh="hip_1" material="gray" class="visual" quat="4.63268e-05 1 0 0" />
        <geom size="0.046 0.02" pos="0 -0.08 0" quat="0.707107 0.707107 0 0" type="cylinder"
          class="collision" />
        <body name="FR_thigh" pos="0 -0.0955 0">
          <inertial pos="-0.00374 0.0223 -0.0327" quat="0.551623 -0.0200632 0.0847635 0.829533"
            mass="1.152"
            diaginertia="0.00594973 0.00584149 0.000878787" />
          <joint name="FR_thigh_joint" class="front_hip" />
          <geom mesh="thigh_mirror_0" material="metal" class="visual" />
          <geom mesh="thigh_mirror_1" material="gray" class="visual" />
          <geom size="0.1065 0.01225 0.017" pos="0 0 -0.1065" quat="0.707107 0 0.707107 0"
            type="box" class="collision" />
          <body name="FR_calf" pos="0 0 -0.213">
            <inertial pos="0.00629595 0.000622121 -0.141417"
              quat="0.703508 -0.00450087 0.00154099 0.710672"
              mass="0.241352" diaginertia="0.0014901 0.00146356 5.31397e-05" />
            <joint name="FR_calf_joint" class="knee" />
            <geom mesh="calf_mirror" material="gray" class="visual" />
            <geom size="0.013 0.06" pos="0.01 0 -0.06" quat="0.995004 0 -0.0998334 0"
              type="cylinder" class="collision" />
            <geom size="0.011 0.0325" pos="0.02 0 -0.148" quat="0.999688 0 0.0249974 0"
              type="cylinder" class="collision" />

            <body name="FR_wheel_link" pos="0 0 -0.2264">
              <inertial pos="-0.0 -0.04 -0.0"
                quat="0.661419 0.248219 0.250051 0.662108" mass="0.98"
                diaginertia="0.003 0.0016 0.0016" />
              <joint name="FR_wheel_joint" pos="0 0 0" axis="0 1 0" />
              <geom type="mesh" rgba="0.15 0.15 0.15 1" mesh="wheel" pos="0 -0.0 0" />
              <geom pos="0 0.0 0" type="mesh" mesh="wheel" class="foot"/>
            </body>

          </body>
        </body>
      </body>
      <body name="RL_hip" pos="-0.1934 0.0465 0">
        <inertial pos="0.0054 0.00194 -0.000105" quat="0.505462 0.498237 0.497014 0.499245"
          mass="0.678"
          diaginertia="0.00088403 0.000596003 0.000479967" />
        <joint name="RL_hip_joint" class="abduction" />
        <geom mesh="hip_0" material="metal" class="visual" quat="4.63268e-05 0 1 0" />
        <geom mesh="hip_1" material="gray" class="visual" quat="4.63268e-05 0 1 0" />
        <geom size="0.046 0.02" pos="0 0.08 0" quat="0.707107 0.707107 0 0" type="cylinder"
          class="collision" />
        <body name="RL_thigh" pos="0 0.0955 0">
          <inertial pos="-0.00374 -0.0223 -0.0327" quat="0.829533 0.0847635 -0.0200632 0.551623"
            mass="1.152"
            diaginertia="0.00594973 0.00584149 0.000878787" />
          <joint name="RL_thigh_joint" class="back_hip" />
          <geom mesh="thigh_0" material="metal" class="visual" />
          <geom mesh="thigh_1" material="gray" class="visual" />
          <geom size="0.1065 0.01225 0.017" pos="0 0 -0.1065" quat="0.707107 0 0.707107 0"
            type="box" class="collision" />
          <body name="RL_calf" pos="0 0 -0.213">
            <inertial pos="0.00629595 -0.000622121 -0.141417"
              quat="0.710672 0.00154099 -0.00450087 0.703508"
              mass="0.241352" diaginertia="0.0014901 0.00146356 5.31397e-05" />
            <joint name="RL_calf_joint" class="knee" />
            <geom mesh="calf" material="gray" class="visual" />
            <geom size="0.013 0.06" pos="0.01 0 -0.06" quat="0.995004 0 -0.0998334 0"
              type="cylinder" class="collision" />
            <geom size="0.011 0.0325" pos="0.02 0 -0.148" quat="0.999688 0 0.0249974 0"
              type="cylinder" class="collision" />

            <body name="RL_wheel_link" pos="0 0 -0.2264">
              <inertial pos="-0.0 0.04 -0.0"
                quat="0.661419 0.248219 0.250051 0.662108" mass="0.98"
                diaginertia="0.003 0.0016 0.0016" />
              <joint name="RL_wheel_joint" pos="0 0 0" axis="0 1 0" />
              <geom type="mesh" rgba="0.15 0.15 0.15 1" mesh="wheel" pos="0 0.0 0"
                quat="0.0 1.0 0.0 0.0" />
              <geom pos="0 0.0 0" quat="0.0 1.0 0.0 0.0" type="mesh" mesh="wheel" class="foot"/>
            </body>

          </body>
        </body>
      </body>
      <body name="RR_hip" pos="-0.1934 -0.0465 0">
        <inertial pos="0.0054 -0.00194 -0.000105" quat="0.499245 0.497014 0.498237 0.505462"
          mass="0.678"
          diaginertia="0.00088403 0.000596003 0.000479967" />
        <joint name="RR_hip_joint" class="abduction" />
        <geom mesh="hip_0" material="metal" class="visual"
          quat="2.14617e-09 4.63268e-05 4.63268e-05 -1" />
        <geom mesh="hip_1" material="gray" class="visual"
          quat="2.14617e-09 4.63268e-05 4.63268e-05 -1" />
        <geom size="0.046 0.02" pos="0 -0.08 0" quat="0.707107 0.707107 0 0" type="cylinder"
          class="collision" />
        <body name="RR_thigh" pos="0 -0.0955 0">
          <inertial pos="-0.00374 0.0223 -0.0327" quat="0.551623 -0.0200632 0.0847635 0.829533"
            mass="1.152"
            diaginertia="0.00594973 0.00584149 0.000878787" />
          <joint name="RR_thigh_joint" class="back_hip" />
          <geom mesh="thigh_mirror_0" material="metal" class="visual" />
          <geom mesh="thigh_mirror_1" material="gray" class="visual" />
          <geom size="0.1065 0.01225 0.017" pos="0 0 -0.1065" quat="0.707107 0 0.707107 0"
            type="box" class="collision" />
          <body name="RR_calf" pos="0 0 -0.213">
            <inertial pos="0.00629595 0.000622121 -0.141417"
              quat="0.703508 -0.00450087 0.00154099 0.710672"
              mass="0.241352" diaginertia="0.0014901 0.00146356 5.31397e-05" />
            <joint name="RR_calf_joint" class="knee" />
            <geom mesh="calf_mirror" material="gray" class="visual" />
            <geom size="0.013 0.06" pos="0.01 0 -0.06" quat="0.995004 0 -0.0998334 0"
              type="cylinder" class="collision" />
            <geom size="0.011 0.0325" pos="0.02 0 -0.148" quat="0.999688 0 0.0249974 0"
              type="cylinder" class="collision" />

            <body name="RR_wheel_link" pos="0 0 -0.2264">
              <inertial pos="-0.0 -0.04 -0.0"
                quat="0.661419 0.248219 0.250051 0.662108" mass="0.98"
                diaginertia="0.003 0.0016 0.0016" />
              <joint name="RR_wheel_joint" pos="0 0 0" axis="0 1 0" />
              <geom type="mesh" rgba="0.15 0.15 0.15 1" mesh="wheel" pos="0 -0.00 0" />
              <geom pos="0 0.0 0" type="mesh" mesh="wheel" class="foot"/>
            </body>

          </body>
        </body>
      </body>
      <body name="arm_base" pos="0.0 0.0 0.05">
          <inertial mass="0.228373962837317" pos="-0.00861913597750766 -6.69095945024908E-05 0.0410099270550501"
                    fullinertia="0.000187936067553932 0.000204828705266307 0.000231563163279888 -6.53520857891701E-07 7.39994953673336E-06 -8.76384398048941E-08"/>
          <geom type="mesh" mesh="arm_base" material="linkgray" group="1"/>
          <body name="link1" pos="0 0 0.074">
              <inertial mass="0.108998907454935" pos="0.000215436966529914 0.000816878307498813 0.0405403765566978"
                        fullinertia="4.04353787761011E-05 5.80031220632913E-05 4.81279730395351E-05 2.54752198315866E-07 2.27878395396439E-07 1.13106632945479E-07 "/>
              <joint name="joint1" pos="0 0 0" limited="true" range="-2.618 2.618" axis="0 0 1" damping="0.05" frictionloss="0.01"/>
              <geom type="mesh" mesh="link1" material="linkgray" group="1"/>
              <body name="link2" pos="0 0 0.049" quat="0.5 -0.5 -0.5 -0.5">
                  <inertial mass="0.209474218151005" pos="0.191716525414641 -0.0117234005667833 0.0008128063118137"
                            diaginertia="0.133886 0.133886 0.0151074"/>
                  <joint name="joint2" limited="true" range="-1.57 1.57" axis="0 0 1" damping="0.05" frictionloss="0.01"/>
                  <geom type="mesh" mesh="link2" material="linkgray" group="1"/>
                  <body name="link3" pos="0.285029571976847 0 0" quat="1 0 0 1">
                      <inertial mass="0.209474218151005"
                                pos="0.161458239158621 -0.0218931046091274 -2.30986755046019E-06"
                                fullinertia="5.71683516981117E-05 0.000134052546704278 0.000141059415822027 5.79507800802695E-07 1.28673392465E-07 2.59580501155443E-08"/>
                      <joint name="joint3" limited="true" range="-1.637 1.33" axis="0 0 1" damping="0.05" frictionloss="0.01"/>
                      <geom type="mesh" mesh="link3" material="linkgray" group="1"/>
                      <body name="link4" pos="0.214751946919796 -0.0219839705141729 0" quat="1 0 1 0">
                          <inertial mass="0.138193015163291"
                                    pos="-0.00283624220926272 -0.000168246655768645 0.0310754925767173"
                                    fullinertia="5.41174524223343E-05 4.13049155520053E-05 4.34805043741736E-05 2.48730458165796E-08 -9.82547279537609E-08 -1.55937539599607E-07"/>
                          <joint name="joint4" limited="true" range="-1.832 1.832" axis="0 0 -1" damping="0.05" frictionloss="0.01"/>
                          <geom type="mesh" mesh="link4" material="linkgray" group="1"/>
                          <body name="link5" pos="0 0 0.0359999999999987" quat="0 1 0 1">
                              <inertial mass="0.139531636700148"
                                        pos="0.0570255157277101 1.43513671547746E-05 0.00209770176364061"
                                        fullinertia="5.39851799511625E-05 4.28793555680474E-05 4.76012426378892E-05 -2.81634169173708E-08 2.14265221666276E-07 1.83802821935451E-08"/>
                              <joint name="joint5" limited="true" range="-1.22 1.22" axis="0 0 -1" damping="0.05" frictionloss="0.01"/>
                              <geom type="mesh" mesh="link5" material="linkgray" group="1"/>
                              <body name="link6" pos="0.0910000000000101 0 -0.00141652148619997" quat="0 -1 0 -1">
                                  <inertial mass="0.15531636700148"
                                            pos="9.41121070072333E-09 0.000341209775988838 0.0342122921883722"
                                            fullinertia="4.31750564711759E-05 9.99756357365307E-05 0.000118282295533688 -2.21295720427027E-08 -3.27825836857102E-12 1.10337380549335E-07"/>
                                  <joint name="joint6" limited="true" range="-3.14 3.14" axis="0 0 -1" damping="0.005" frictionloss="0.01"/>
                                  <geom type="mesh" mesh="link6" material="linkgray" group="1"/>
                                  <body name="link7" pos="0 0 0.13503" quat="1 1 1 1">
                                      <inertial mass="0.001"
                                                pos="-0.000277795893713934 -0.046767350270289 -0.00921029791141448"
                                                fullinertia="9.99782474142963E-06 6.17952362333486E-06 1.42102248648757E-05 -1.57547666236405E-07 2.71355834243046E-08 1.58939503259658E-06"/>
                                      <joint name="joint7" range="-0.038 0" type="slide" damping="0.005" frictionloss="0.01"/>
                                      <geom type="mesh" mesh="link7" material="linkgray" group="1"/>

                                  </body>
                                  <body name="link8" pos="0 0 0.13503" quat="1 -1 -1 1">
                                      <inertial mass="0.001"
                                                pos="0.000277795911672651 0.0467673513153836 -0.00921029799058583"
                                                fullinertia="9.99782474142963E-06 6.17952362333486E-06 1.42102248648757E-05 -1.57547666236405E-07 2.71355834243046E-08 1.58939503259658E-06"/>
                                      <joint name="joint8" range="-0.038 0" type="slide" damping="0.005" frictionloss="0.01"/>
                                      <geom type="mesh" mesh="link8" material="linkgray" group="1"/>

                                  </body>
                              </body>
                          </body>
                      </body>
                  </body>
              </body>
          </body>
      </body>
    </body>
  </worldbody>

  <equality>
    <joint name="gripper_slide_joint_eq" joint1="joint7" joint2="joint8"/>
  </equality>

  <actuator>
    <motor class="abduction" name="FR_hip" joint="FR_hip_joint" />
    <motor class="hip" name="FR_thigh" joint="FR_thigh_joint" />
    <motor class="knee" name="FR_calf" joint="FR_calf_joint" />

    <motor class="abduction" name="FL_hip" joint="FL_hip_joint" />
    <motor class="hip" name="FL_thigh" joint="FL_thigh_joint" />
    <motor class="knee" name="FL_calf" joint="FL_calf_joint" />

    <motor class="abduction" name="RR_hip" joint="RR_hip_joint" />
    <motor class="hip" name="RR_thigh" joint="RR_thigh_joint" />
    <motor class="knee" name="RR_calf" joint="RR_calf_joint" />

    <motor class="abduction" name="RL_hip" joint="RL_hip_joint" />
    <motor class="hip" name="RL_thigh" joint="RL_thigh_joint" />
    <motor class="knee" name="RL_calf" joint="RL_calf_joint" />

    <motor ctrlrange="-15 15" name="FR_wheel" joint="FR_wheel_joint" />
    <motor ctrlrange="-15 15" name="FL_wheel" joint="FL_wheel_joint" />
    <motor ctrlrange="-15 15" name="RR_wheel" joint="RR_wheel_joint" />
    <motor ctrlrange="-15 15" name="RL_wheel" joint="RL_wheel_joint" />

    <motor ctrllimited="true" ctrlrange="-100.0 100.0" forcerange="-100.0 100.0" joint="joint1" name="actuator1"/>
    <motor ctrllimited="true" ctrlrange="-100.0 100.0" forcerange="-100.0 100.0" joint="joint2" name="actuator2"/>
    <motor ctrllimited="true" ctrlrange="-100.0 100.0" forcerange="-100.0 100.0" joint="joint3" name="actuator3"/>
    <motor ctrllimited="true" ctrlrange="-100.0 100.0" forcerange="-100.0 100.0" joint="joint4" name="actuator4"/>
    <motor ctrllimited="true" ctrlrange="-100.0 100.0" forcerange="-100.0 100.0" joint="joint5" name="actuator5"/>
    <motor ctrllimited="true" ctrlrange="-100.0 100.0" forcerange="-100.0 100.0" joint="joint6" name="actuator6"/>
  </actuator>

  <sensor>
    <jointpos name="FR_hip_pos" joint="FR_hip_joint" />
    <jointpos name="FR_thigh_pos" joint="FR_thigh_joint" />
    <jointpos name="FR_calf_pos" joint="FR_calf_joint" />

    <jointpos name="FL_hip_pos" joint="FL_hip_joint" />
    <jointpos name="FL_thigh_pos" joint="FL_thigh_joint" />
    <jointpos name="FL_calf_pos" joint="FL_calf_joint" />

    <jointpos name="RR_hip_pos" joint="RR_hip_joint" />
    <jointpos name="RR_thigh_pos" joint="RR_thigh_joint" />
    <jointpos name="RR_calf_pos" joint="RR_calf_joint" />
    
    <jointpos name="RL_hip_pos" joint="RL_hip_joint" />
    <jointpos name="RL_thigh_pos" joint="RL_thigh_joint" />
    <jointpos name="RL_calf_pos" joint="RL_calf_joint" />

    <jointpos name="FR_wheel_pos" joint="FR_wheel_joint" />
    <jointpos name="FL_wheel_pos" joint="FL_wheel_joint" />
    <jointpos name="RR_wheel_pos" joint="RR_wheel_joint" />
    <jointpos name="RL_wheel_pos" joint="RL_wheel_joint" />

    <jointvel name="FR_hip_vel" joint="FR_hip_joint" />
    <jointvel name="FR_thigh_vel" joint="FR_thigh_joint" />
    <jointvel name="FR_calf_vel" joint="FR_calf_joint" />
    <jointvel name="FL_hip_vel" joint="FL_hip_joint" />
    <jointvel name="FL_thigh_vel" joint="FL_thigh_joint" />
    <jointvel name="FL_calf_vel" joint="FL_calf_joint" />
    <jointvel name="RR_hip_vel" joint="RR_hip_joint" />
    <jointvel name="RR_thigh_vel" joint="RR_thigh_joint" />
    <jointvel name="RR_calf_vel" joint="RR_calf_joint" />
    <jointvel name="RL_hip_vel" joint="RL_hip_joint" />
    <jointvel name="RL_thigh_vel" joint="RL_thigh_joint" />
    <jointvel name="RL_calf_vel" joint="RL_calf_joint" />

    <jointvel name="FR_wheel_vel" joint="FR_wheel_joint" noise="0.0"/>
    <jointvel name="FL_wheel_vel" joint="FL_wheel_joint" noise="0.0"/>
    <jointvel name="RR_wheel_vel" joint="RR_wheel_joint" noise="0.0"/>
    <jointvel name="RL_wheel_vel" joint="RL_wheel_joint" noise="0.0"/>

    <jointactuatorfrc name="FR_hip_torque" joint="FR_hip_joint" noise="0.01" />
    <jointactuatorfrc name="FR_thigh_torque" joint="FR_thigh_joint" noise="0.01" />
    <jointactuatorfrc name="FR_calf_torque" joint="FR_calf_joint" noise="0.01" />
    <jointactuatorfrc name="FL_hip_torque" joint="FL_hip_joint" noise="0.01" />
    <jointactuatorfrc name="FL_thigh_torque" joint="FL_thigh_joint" noise="0.01" />
    <jointactuatorfrc name="FL_calf_torque" joint="FL_calf_joint" noise="0.01" />
    <jointactuatorfrc name="RR_hip_torque" joint="RR_hip_joint" noise="0.01" />
    <jointactuatorfrc name="RR_thigh_torque" joint="RR_thigh_joint" noise="0.01" />
    <jointactuatorfrc name="RR_calf_torque" joint="RR_calf_joint" noise="0.01" />
    <jointactuatorfrc name="RL_hip_torque" joint="RL_hip_joint" noise="0.01" />
    <jointactuatorfrc name="RL_thigh_torque" joint="RL_thigh_joint" noise="0.01" />
    <jointactuatorfrc name="RL_calf_torque" joint="RL_calf_joint" noise="0.01" />

    <jointactuatorfrc name="FR_wheel_torque" joint="FR_wheel_joint" />
    <jointactuatorfrc name="FL_wheel_torque" joint="FL_wheel_joint" />
    <jointactuatorfrc name="RR_wheel_torque" joint="RR_wheel_joint" />
    <jointactuatorfrc name="RL_wheel_torque" joint="RL_wheel_joint" />

    <framequat name="imu_quat" objtype="site" objname="imu" noise="0.0"/>
    <gyro name="imu_gyro" site="imu" noise="0.0"/>
    <accelerometer name="imu_acc" site="imu" />

    <framepos name="frame_pos" objtype="site" objname="imu" />
    <framelinvel name="frame_vel" objtype="site" objname="imu" />
  </sensor>

</mujoco>