<?xml version='1.0' encoding='utf-8'?>
<robot name="go2w_piper_description">

  <link name="base">
    <inertial>
      <origin xyz="0.021112 0 -0.005366" rpy="0 0 0" />
      <mass value="6.921" />
      <inertia ixx="0.02448" ixy="0.00012166" ixz="0.0014849" iyy="0.098077" iyz="-3.12E-05" izz="0.107" />
    </inertial>
    <visual>
      <origin xyz="0 0 0" rpy="0 0 0" />
      <geometry>
        <mesh filename="../meshes/go2w/base.dae" />
      </geometry>
      <material name="深色橡胶_001-effect"><color rgba="0.6717055 0.6924257 0.7742702 1" /></material><material name="白色logo_001-effect"><color rgba="1 1 1 1" /></material><material name="黑色贴纸_007-effect"><color rgba="0.009018 0.009018 0.009018 1" /></material><material name="黑色金属_007-effect"><color rgba="0.01341 0.01341 0.01341 1" /></material><material name="黑色塑料_003-effect"><color rgba="0.023455 0.023455 0.023455 1" /></material></visual>
    <collision>
      <origin rpy="0 0 0" xyz="0 0 0" />
      <geometry>
        <box size="0.3762 0.0935 0.114" />
      </geometry>
    </collision>
  </link>

  <link name="Head_upper">
    <inertial>
      <origin xyz="0 0 0" rpy="0 0 0" />
      <mass value="0.001" />
      <inertia ixx="9.6e-06" ixy="0" ixz="0" iyy="9.6e-06" iyz="0" izz="9.6e-06" />
    </inertial>
    <collision>
      <origin xyz="0 0 0" rpy="0 0 0" />
      <geometry>
        <cylinder radius="0.06" length="0.09" />
      </geometry>
    </collision>
  </link>
  <joint name="Head_upper_joint" type="fixed">
    <origin xyz="0.285 0 0.01" rpy="0 0 0" />
    <parent link="base" />
    <child link="Head_upper" />
    <axis xyz="0 0 0" />
  </joint>
  <link name="Head_lower">
    <inertial>
      <origin xyz="0 0 0" rpy="0 0 0" />
      <mass value="0.001" />
      <inertia ixx="9.6e-06" ixy="0" ixz="0" iyy="9.6e-06" iyz="0" izz="9.6e-06" />
    </inertial>
    <collision>
      <origin xyz="0 0 0" rpy="0 0 0" />
      <geometry>
        <sphere radius="0.06" />
      </geometry>
    </collision>
  </link>
  <joint name="Head_lower_joint" type="fixed">
    <origin xyz="0.008 0 -0.07" rpy="0 0 0" />
    <parent link="Head_upper" />
    <child link="Head_lower" />
    <axis xyz="0 0 0" />
  </joint>

  <link name="FL_hip">
    <inertial>
      <origin xyz="-0.0054 0.00194 -0.000105" rpy="0 0 0" />
      <mass value="0.678" />
      <inertia ixx="0.00048" ixy="-3.01E-06" ixz="1.11E-06" iyy="0.000884" iyz="-1.42E-06" izz="0.000596" />
    </inertial>
    <visual>
      <origin xyz="0 0 0" rpy="0 0 0" />
      <geometry>
        <mesh filename="../meshes/go2w/hip.dae" />
      </geometry>
      <material name="深色橡胶_001-effect"><color rgba="0.6717055 0.6924257 0.7742702 1" /></material><material name="Material-effect"><color rgba="0.9 0.95 0.95 1" /></material></visual>
    <collision>
      <origin rpy="1.5707963267948966 0 0" xyz="0 0.08 0" />
      <geometry>
        <cylinder length="0.04" radius="0.046" />
      </geometry>
    </collision>
  </link>
  <joint name="FL_hip_joint" type="revolute">
    <origin xyz="0.1934 0.0465 0" rpy="0 0 0" />
    <parent link="base" />
    <child link="FL_hip" />
    <axis xyz="1 0 0" />
    <limit lower="-1.0472" upper="1.0472" effort="23.7" velocity="30.1" />
  </joint>
  <link name="FL_thigh">
    <inertial>
      <origin xyz="-0.00374 -0.0223 -0.0327" rpy="0 0 0" />
      <mass value="1.152" />
      <inertia ixx="0.00584" ixy="8.72E-05" ixz="-0.000289" iyy="0.0058" iyz="0.000808" izz="0.00103" />
    </inertial>
    <visual>
      <origin xyz="0 0 0" rpy="0 0 0" />
      <geometry>
        <mesh filename="../meshes/go2w/thigh.dae" />
      </geometry>
      <material name="深色橡胶_003-effect"><color rgba="0.6717055 0.6924257 0.7742702 1" /></material><material name="Material_009-effect"><color rgba="0.9 0.95 0.95 1" /></material></visual>
    <collision>
      <origin rpy="0 1.5707963267948966 0" xyz="0 0 -0.1065" />
      <geometry>
        <box size="0.11 0.0245 0.034" />
      </geometry>
    </collision>
  </link>
  <joint name="FL_thigh_joint" type="revolute">
    <origin xyz="0 0.0955 0" rpy="0 0 0" />
    <parent link="FL_hip" />
    <child link="FL_thigh" />
    <axis xyz="0 1 0" />
    <limit lower="-1.5707963267948966" upper="3.4907" effort="23.7" velocity="30.1" />
  </joint>
  <link name="FL_calf">
    <inertial>
      <origin xyz="0.00548 -0.000975 -0.115" rpy="0 0 0" />
      <mass value="0.154" />
      <inertia ixx="0.00108" ixy="3.4E-07" ixz="1.72E-05" iyy="0.0011" iyz="8.28E-06" izz="3.29E-05" />
    </inertial>
    <visual>
      <origin xyz="0 0 0" rpy="-1.5707963267948966 0 0" />
      <geometry>
        <mesh filename="../meshes/go2w/calf.stl" />
      </geometry>
      <material name="">
        <color rgba="1 1 1 1" />
      </material>
    </visual>
    <collision>
      <origin rpy="0 -0.21 0" xyz="0.008 0 -0.06" />
      <geometry>
        <cylinder length="0.12" radius="0.012" />
      </geometry>
    </collision>
  </link>
  <joint name="FL_calf_joint" type="revolute">
    <origin xyz="0 0 -0.213" rpy="0 0 0" />
    <parent link="FL_thigh" />
    <child link="FL_calf" />
    <axis xyz="0 1 0" />
    <limit lower="-2.7227" upper="-0.83776" effort="35.55" velocity="20.07" />
  </joint>
  <link name="FL_calflower">
    <collision>
      <origin rpy="0 0 0" xyz="0 0 0" />
      <geometry>
        <cylinder length="0.065" radius="0.011" />
      </geometry>
    </collision>
  </link>
  <joint name="FL_calflower_joint" type="fixed">
    <origin xyz="0.020 0 -0.148" rpy="0 0.05 0" />
    <parent link="FL_calf" />
    <child link="FL_calflower" />
    <axis xyz="0 0 0" />
  </joint>
  <link name="FL_calflower1">
    <collision>
      <origin rpy="0 0 0" xyz="0 0 0" />
      <geometry>
        <cylinder length="0.03" radius="0.0155" />
      </geometry>
    </collision>
  </link>
  <joint name="FL_calflower1_joint" type="fixed">
    <origin xyz="-0.01 0 -0.04" rpy="0 0.48 0" />
    <parent link="FL_calflower" />
    <child link="FL_calflower1" />
    <axis xyz="0 0 0" />
  </joint>
  <link name="FL_foot_motor">
    <inertial>
      <origin xyz="0 0.0 0" rpy="0 0 0" />
      <mass value="0.646" />
      <inertia ixx="0.001" ixy="0" ixz="0" iyy="0.0016" iyz="0" izz="0.001" />
    </inertial>
    <collision>
      <origin rpy="1.5707963267948966 0 0" xyz="0 0 0" />
      <geometry>
        <cylinder length="0.05" radius="0.05" />
      </geometry>
    </collision>
  </link>
  <joint name="FL_foot_motor_joint" type="fixed">
    <origin xyz="-0.00 0.01 -0.2264" rpy="0 0.0 0" />
    <parent link="FL_calf" />
    <child link="FL_foot_motor" />
    <axis xyz="0 0 0" />
  </joint>
  <link name="FL_foot">
    <inertial>
      <origin xyz="0 0.06 0" rpy="0 0 0" />
      <mass value="0.520" />
      <inertia ixx="0.0007" ixy="0" ixz="0" iyy="0.0012" iyz="0" izz="0.0007" />
    </inertial>
    <visual>
      <origin xyz="0 0 0" rpy="0 0 0" />
      <geometry>
        <mesh filename="../meshes/go2w/left_wheel.dae" />
      </geometry>
      <material name="">
        <color rgba="1 1 1 1" />
      </material>
    </visual>
    <collision>
      <origin rpy="1.5707963267948966 0 0" xyz="0 0.048 0" />
      <geometry>
        <cylinder length="0.048" radius="0.086" />
      </geometry>
    </collision>
  </link>
  <joint name="FL_foot_joint" type="revolute">
    <origin xyz="0 0 -0.2264" rpy="0 0 0" />
    <parent link="FL_calf" />
    <child link="FL_foot" />
    <axis xyz="0 1 0" />
    <limit effort="23.7" velocity="30.1" />
  </joint>
  
  <link name="FR_hip">
    <inertial>
      <origin xyz="-0.0054 -0.00194 -0.000105" rpy="0 0 0" />
      <mass value="0.678" />
      <inertia ixx="0.00048" ixy="3.01E-06" ixz="1.11E-06" iyy="0.000884" iyz="1.42E-06" izz="0.000596" />
    </inertial>
    <visual>
      <origin xyz="0 0 0" rpy="3.1415 0 0" />
      <geometry>
        <mesh filename="../meshes/go2w/hip.dae" />
      </geometry>
      <material name="深色橡胶_001-effect"><color rgba="0.6717055 0.6924257 0.7742702 1" /></material><material name="Material-effect"><color rgba="0.9 0.95 0.95 1" /></material></visual>
    <collision>
      <origin rpy="1.5707963267948966 0 0" xyz="0 -0.08 0" />
      <geometry>
        <cylinder length="0.04" radius="0.046" />
      </geometry>
    </collision>
  </link>
  <joint name="FR_hip_joint" type="revolute">
    <origin xyz="0.1934 -0.0465 0" rpy="0 0 0" />
    <parent link="base" />
    <child link="FR_hip" />
    <axis xyz="1 0 0" />
    <limit lower="-1.0472" upper="1.0472" effort="23.7" velocity="30.1" />
  </joint>
  <link name="FR_thigh">
    <inertial>
      <origin xyz="-0.00374 0.0223 -0.0327" rpy="0 0 0" />
      <mass value="1.152" />
      <inertia ixx="0.00584" ixy="-8.72E-05" ixz="-0.000289" iyy="0.0058" iyz="-0.000808" izz="0.00103" />
    </inertial>
    <visual>
      <origin xyz="0 0 0" rpy="0 0 0" />
      <geometry>
        <mesh filename="../meshes/go2w/thigh_mirror.dae" />
      </geometry>
      <material name="深色橡胶_012-effect"><color rgba="0.6717055 0.6924257 0.7742702 1" /></material><material name="Material_011-effect"><color rgba="0.9 0.95 0.95 1" /></material></visual>
    <collision>
      <origin rpy="0 1.5707963267948966 0" xyz="0 0 -0.1065" />
      <geometry>
        <box size="0.11 0.0245 0.034" />
      </geometry>
    </collision>
  </link>
  <joint name="FR_thigh_joint" type="revolute">
    <origin xyz="0 -0.0955 0" rpy="0 0 0" />
    <parent link="FR_hip" />
    <child link="FR_thigh" />
    <axis xyz="0 1 0" />
    <limit lower="-1.5707963267948966" upper="3.4907" effort="23.7" velocity="30.1" />
  </joint>
  <link name="FR_calf">
    <inertial>
      <origin xyz="0.00548 0.000975 -0.115" rpy="0 0 0" />
      <mass value="0.154" />
      <inertia ixx="0.00108" ixy="-3.4E-07" ixz="1.72E-05" iyy="0.0011" iyz="-8.28E-06" izz="3.29E-05" />
    </inertial>
    <visual>
      <origin xyz="0 0 0" rpy="-1.5707963267948966 0 0" />
      <geometry>
        <mesh filename="../meshes/go2w/calf_mirror.stl" />
      </geometry>
      <material name="">
        <color rgba="1 1 1 1" />
      </material>
    </visual>
    <collision>
      <origin rpy="0 -0.2 0" xyz="0.01 0 -0.06" />
      <geometry>
        <cylinder length="0.12" radius="0.013" />
      </geometry>
    </collision>
  </link>
  <joint name="FR_calf_joint" type="revolute">
    <origin xyz="0 0 -0.213" rpy="0 0 0" />
    <parent link="FR_thigh" />
    <child link="FR_calf" />
    <axis xyz="0 1 0" />
    <limit lower="-2.7227" upper="-0.83776" effort="35.55" velocity="20.07" />
  </joint>
  <link name="FR_calflower">
    <collision>
      <origin rpy="0 0 0" xyz="0 0 0" />
      <geometry>
        <cylinder length="0.065" radius="0.011" />
      </geometry>
    </collision>
  </link>
  <joint name="FR_calflower_joint" type="fixed">
    <origin xyz="0.020 0 -0.148" rpy="0 0.05 0" />
    <parent link="FR_calf" />
    <child link="FR_calflower" />
    <axis xyz="0 0 0" />
  </joint>
  <link name="FR_calflower1">
    <collision>
      <origin rpy="0 0 0" xyz="0 0 0" />
      <geometry>
        <cylinder length="0.03" radius="0.0155" />
      </geometry>
    </collision>
  </link>
  <joint name="FR_calflower1_joint" type="fixed">
    <origin xyz="-0.01 0 -0.04" rpy="0 0.48 0" />
    <parent link="FR_calflower" />
    <child link="FR_calflower1" />
    <axis xyz="0 0 0" />
  </joint>
  <link name="FR_foot_motor">
    <inertial>
      <origin xyz="0 0.0 0" rpy="0 0 0" />
      <mass value="0.646" />
      <inertia ixx="0.001" ixy="0" ixz="0" iyy="0.0016" iyz="0" izz="0.001" />
    </inertial>
    <collision>
      <origin rpy="1.5707963267948966 0 0" xyz="0 0 0" />
      <geometry>
        <cylinder length="0.05" radius="0.05" />
      </geometry>
    </collision>
  </link>
  <joint name="FR_foot_motor_joint" type="fixed">
    <origin xyz="0.0 -0.01 -0.2264" rpy="0 0.0 0" />
    <parent link="FR_calf" />
    <child link="FR_foot_motor" />
    <axis xyz="0 0 0" />
  </joint>
  <link name="FR_foot">
    <inertial>
      <origin xyz="0 -0.06 0" rpy="0 0 0" />
      <mass value="0.520" />
      <inertia ixx="0.0007" ixy="0" ixz="0" iyy="0.0012" iyz="0" izz="0.0007" />
    </inertial>
    <visual>
      <origin xyz="0 0 0" rpy="0 0 0" />
      <geometry>
        <mesh filename="../meshes/go2w/right_wheel.dae" />
      </geometry>
      <material name="">
        <color rgba="1 1 1 1" />
      </material>
    </visual>
    <collision>
      <origin rpy="1.5707963267948966 0 0" xyz="0 -0.048 0" />
      <geometry>
        <cylinder length="0.048" radius="0.086" />
      </geometry>
    </collision>
  </link>
  <joint name="FR_foot_joint" type="revolute">
    <origin xyz="0 0 -0.2264" rpy="0 0 0" />
    <parent link="FR_calf" />
    <child link="FR_foot" />
    <axis xyz="0 1 0" />
    <limit effort="23.7" velocity="30.1" />
  </joint>

  <link name="RL_hip">
    <inertial>
      <origin xyz="0.0054 0.00194 -0.000105" rpy="0 0 0" />
      <mass value="0.678" />
      <inertia ixx="0.00048" ixy="3.01E-06" ixz="-1.11E-06" iyy="0.000884" iyz="-1.42E-06" izz="0.000596" />
    </inertial>
    <visual>
      <origin xyz="0 0 0" rpy="0 3.1415 0" />
      <geometry>
        <mesh filename="../meshes/go2w/hip.dae" />
      </geometry>
      <material name="深色橡胶_001-effect"><color rgba="0.6717055 0.6924257 0.7742702 1" /></material><material name="Material-effect"><color rgba="0.9 0.95 0.95 1" /></material></visual>
    <collision>
      <origin rpy="1.5707963267948966 0 0" xyz="0 0.08 0" />
      <geometry>
        <cylinder length="0.04" radius="0.046" />
      </geometry>
    </collision>
  </link>
  <joint name="RL_hip_joint" type="revolute">
    <origin xyz="-0.1934 0.0465 0" rpy="0 0 0" />
    <parent link="base" />
    <child link="RL_hip" />
    <axis xyz="1 0 0" />
    <limit lower="-1.0472" upper="1.0472" effort="23.7" velocity="30.1" />
  </joint>
  <link name="RL_thigh">
    <inertial>
      <origin xyz="-0.00374 -0.0223 -0.0327" rpy="0 0 0" />
      <mass value="1.152" />
      <inertia ixx="0.00584" ixy="8.72E-05" ixz="-0.000289" iyy="0.0058" iyz="0.000808" izz="0.00103" />
    </inertial>
    <visual>
      <origin xyz="0 0 0" rpy="0 0 0" />
      <geometry>
        <mesh filename="../meshes/go2w/thigh.dae" />
      </geometry>
      <material name="深色橡胶_003-effect"><color rgba="0.6717055 0.6924257 0.7742702 1" /></material><material name="Material_009-effect"><color rgba="0.9 0.95 0.95 1" /></material></visual>
    <collision>
      <origin rpy="0 1.5707963267948966 0" xyz="0 0 -0.1065" />
      <geometry>
        <box size="0.11 0.0245 0.034" />
      </geometry>
    </collision>
  </link>
  <joint name="RL_thigh_joint" type="revolute">
    <origin xyz="0 0.0955 0" rpy="0 0 0" />
    <parent link="RL_hip" />
    <child link="RL_thigh" />
    <axis xyz="0 1 0" />
    <limit lower="-0.5236" upper="4.5379" effort="23.7" velocity="30.1" />
  </joint>
  <link name="RL_calf">
    <inertial>
      <origin xyz="0.00548 -0.000975 -0.115" rpy="0 0 0" />
      <mass value="0.154" />
      <inertia ixx="0.00108" ixy="3.4E-07" ixz="1.72E-05" iyy="0.0011" iyz="8.28E-06" izz="3.29E-05" />
    </inertial>
    <visual>
      <origin xyz="0 0 0" rpy="-1.5707963267948966 0 0" />
      <geometry>
        <mesh filename="../meshes/go2w/calf.stl" />
      </geometry>
      <material name="">
        <color rgba="1 1 1 1" />
      </material>
    </visual>
    <collision>
      <origin rpy="0 -0.2 0" xyz="0.01 0 -0.06" />
      <geometry>
        <cylinder length="0.12" radius="0.013" />
      </geometry>
    </collision>
  </link>
  <joint name="RL_calf_joint" type="revolute">
    <origin xyz="0 0 -0.213" rpy="0 0 0" />
    <parent link="RL_thigh" />
    <child link="RL_calf" />
    <axis xyz="0 1 0" />
    <limit lower="-2.7227" upper="-0.83776" effort="35.55" velocity="20.07" />
  </joint>
  <link name="RL_calflower">
    <collision>
      <origin rpy="0 0 0" xyz="0 0 0" />
      <geometry>
        <cylinder length="0.065" radius="0.011" />
      </geometry>
    </collision>
  </link>
  <joint name="RL_calflower_joint" type="fixed">
    <origin xyz="0.020 0 -0.148" rpy="0 0.05 0" />
    <parent link="RL_calf" />
    <child link="RL_calflower" />
    <axis xyz="0 0 0" />
  </joint>
  <link name="RL_calflower1">
    <collision>
      <origin rpy="0 0 0" xyz="0 0 0" />
      <geometry>
        <cylinder length="0.03" radius="0.0155" />
      </geometry>
    </collision>
  </link>
  <joint name="RL_calflower1_joint" type="fixed">
    <origin xyz="-0.01 0 -0.04" rpy="0 0.48 0" />
    <parent link="RL_calflower" />
    <child link="RL_calflower1" />
    <axis xyz="0 0 0" />
  </joint>
  <link name="RL_foot_motor">
    <inertial>
        <origin xyz="0 0.0 0" rpy="0 0 0" />
        <mass value="0.646" />
        <inertia ixx="0.001" ixy="0" ixz="0" iyy="0.0016" iyz="0" izz="0.001" />
    </inertial>
    <collision>
        <origin rpy="1.5707963267948966 0 0" xyz="0 0 0" />
        <geometry>
        <cylinder length="0.05" radius="0.05" />
        </geometry>
    </collision>
  </link>
  <joint name="RL_foot_motor_joint" type="fixed">
    <origin xyz="0.00 0.01 -0.2264" rpy="0 0.0 0" />
    <parent link="RL_calf" />
    <child link="RL_foot_motor" />
    <axis xyz="0 0 0" />
  </joint>
  <link name="RL_foot">
    <inertial>
      <origin xyz="0 0.06 0" rpy="0 0 0" />
      <mass value="0.520" />
      <inertia ixx="0.0007" ixy="0" ixz="0" iyy="0.0012" iyz="0" izz="0.0007" />
    </inertial>
    <visual>
      <origin xyz="0 0 0" rpy="0 0 0" />
      <geometry>
        <mesh filename="../meshes/go2w/left_wheel.dae" />
      </geometry>
      <material name="">
        <color rgba="1 1 1 1" />
      </material>
    </visual>
    <collision>
      <origin rpy="1.5707963267948966 0 0" xyz="0 0.048 0" />
      <geometry>
        <cylinder length="0.048" radius="0.086" />
      </geometry>
    </collision>
  </link>
  <joint name="RL_foot_joint" type="revolute">
    <origin xyz="0.0 0 -0.2264" rpy="0 0 0" />
    <parent link="RL_calf" />
    <child link="RL_foot" />
    <axis xyz="0 1 0" />
    <limit effort="23.7" velocity="30.1" />
  </joint>

  <link name="RR_hip">
    <inertial>
      <origin xyz="0.0054 -0.00194 -0.000105" rpy="0 0 0" />
      <mass value="0.678" />
      <inertia ixx="0.00048" ixy="-3.01E-06" ixz="-1.11E-06" iyy="0.000884" iyz="1.42E-06" izz="0.000596" />
    </inertial>
    <visual>
      <origin xyz="0 0 0" rpy="3.1415 3.1415 0" />
      <geometry>
        <mesh filename="../meshes/go2w/hip.dae" />
      </geometry>
      <material name="深色橡胶_001-effect"><color rgba="0.6717055 0.6924257 0.7742702 1" /></material><material name="Material-effect"><color rgba="0.9 0.95 0.95 1" /></material></visual>
    <collision>
      <origin rpy="1.5707963267948966 0 0" xyz="0 -0.08 0" />
      <geometry>
        <cylinder length="0.04" radius="0.046" />
      </geometry>
    </collision>
  </link>
  <joint name="RR_hip_joint" type="revolute">
    <origin xyz="-0.1934 -0.0465 0" rpy="0 0 0" />
    <parent link="base" />
    <child link="RR_hip" />
    <axis xyz="1 0 0" />
    <limit lower="-1.0472" upper="1.0472" effort="23.7" velocity="30.1" />
  </joint>
  <link name="RR_thigh">
    <inertial>
      <origin xyz="-0.00374 0.0223 -0.0327" rpy="0 0 0" />
      <mass value="1.152" />
      <inertia ixx="0.00584" ixy="-8.72E-05" ixz="-0.000289" iyy="0.0058" iyz="-0.000808" izz="0.00103" />
    </inertial>
    <visual>
      <origin xyz="0 0 0" rpy="0 0 0" />
      <geometry>
        <mesh filename="../meshes/go2w/thigh_mirror.dae" />
      </geometry>
      <material name="深色橡胶_012-effect"><color rgba="0.6717055 0.6924257 0.7742702 1" /></material><material name="Material_011-effect"><color rgba="0.9 0.95 0.95 1" /></material></visual>
    <collision>
      <origin rpy="0 1.5707963267948966 0" xyz="0 0 -0.1065" />
      <geometry>
        <box size="0.11 0.0245 0.034" />
      </geometry>
    </collision>
  </link>
  <joint name="RR_thigh_joint" type="revolute">
    <origin xyz="0 -0.0955 0" rpy="0 0 0" />
    <parent link="RR_hip" />
    <child link="RR_thigh" />
    <axis xyz="0 1 0" />
    <limit lower="-0.5236" upper="4.5379" effort="23.7" velocity="30.1" />
  </joint>
  <link name="RR_calf">
    <inertial>
      <origin xyz="0.00548 0.000975 -0.115" rpy="0 0 0" />
      <mass value="0.154" />
      <inertia ixx="0.00108" ixy="-3.4E-07" ixz="1.72E-05" iyy="0.0011" iyz="-8.28E-06" izz="3.29E-05" />
    </inertial>
    <visual>
      <origin xyz="0 0 0" rpy="-1.5707963267948966 0 0" />
      <geometry>
        <mesh filename="../meshes/go2w/calf_mirror.stl" />
      </geometry>
      <material name="">
        <color rgba="1 1 1 1" />
      </material>
    </visual>
    <collision>
      <origin rpy="0 -0.2 0" xyz="0.01 0 -0.06" />
      <geometry>
        <cylinder length="0.12" radius="0.013" />
      </geometry>
    </collision>
  </link>
  <joint name="RR_calf_joint" type="revolute">
    <origin xyz="0 0 -0.213" rpy="0 0 0" />
    <parent link="RR_thigh" />
    <child link="RR_calf" />
    <axis xyz="0 1 0" />
    <limit lower="-2.7227" upper="-0.83776" effort="35.55" velocity="20.07" />
  </joint>
  <link name="RR_calflower">
    <collision>
      <origin rpy="0 0 0" xyz="0 0 0" />
      <geometry>
        <cylinder length="0.065" radius="0.011" />
      </geometry>
    </collision>
  </link>
  <joint name="RR_calflower_joint" type="fixed">
    <origin xyz="0.020 0 -0.148" rpy="0 0.05 0" />
    <parent link="RR_calf" />
    <child link="RR_calflower" />
    <axis xyz="0 0 0" />
  </joint>
  <link name="RR_calflower1">
    <collision>
      <origin rpy="0 0 0" xyz="0 0 0" />
      <geometry>
        <cylinder length="0.03" radius="0.0155" />
      </geometry>
    </collision>
  </link>
  <joint name="RR_calflower1_joint" type="fixed">
    <origin xyz="-0.01 0 -0.04" rpy="0 0.48 0" />
    <parent link="RR_calflower" />
    <child link="RR_calflower1" />
    <axis xyz="0 0 0" />
  </joint>
  <link name="RR_foot_motor">
    <inertial>
        <origin xyz="0 0.0 0" rpy="0 0 0" />
        <mass value="0.646" />
        <inertia ixx="0.001" ixy="0" ixz="0" iyy="0.0016" iyz="0" izz="0.001" />
    </inertial>
    <collision>
        <origin rpy="1.5707963267948966 0 0" xyz="0 0 0" />
        <geometry>
        <cylinder length="0.05" radius="0.05" />
        </geometry>
    </collision>
  </link>
  <joint name="RR_foot_motor_joint" type="fixed">
    <origin xyz="0.00 -0.01 -0.2264" rpy="0 0.0 0" />
    <parent link="RR_calf" />
    <child link="RR_foot_motor" />
    <axis xyz="0 0 0" />
  </joint>
  <link name="RR_foot">
    <inertial>
      <origin xyz="0 -0.06 0" rpy="0 0 0" />
      <mass value="0.520" />
      <inertia ixx="0.0007" ixy="0" ixz="0" iyy="0.0012" iyz="0" izz="0.0007" />
    </inertial>
    <visual>
      <origin xyz="0 0 0" rpy="0 0 0" />
      <geometry>
        <mesh filename="../meshes/go2w/right_wheel.dae" />
      </geometry>
      <material name="">
        <color rgba="1 1 1 1" />
      </material>
    </visual>
    <collision>
      <origin rpy="1.5707963267948966 0 0" xyz="0 -0.048 0" />
      <geometry>
        <cylinder length="0.048" radius="0.086" />
      </geometry>
    </collision>
  </link>
  <joint name="RR_foot_joint" type="revolute">
    <origin xyz="-0.0 0 -0.2264" rpy="0 0 0" />
    <parent link="RR_calf" />
    <child link="RR_foot" />
    <axis xyz="0 1 0" />
    <limit effort="23.7" velocity="30.1" />
  </joint>

  <link name="imu">
    <inertial>
      <origin xyz="0 0 0" rpy="0 0 0" />
      <mass value="0" />
      <inertia ixx="0" ixy="0" ixz="0" iyy="0" iyz="0" izz="0" />
    </inertial>
  </link>
  <joint name="imu_joint" type="fixed">
    <origin xyz="-0.02557 0 0.04232" rpy="0 0 0" />
    <parent link="base" />
    <child link="imu" />
    <axis xyz="0 0 0" />
  </joint>
  <link name="radar">
    <inertial>
      <origin xyz="0 0 0" rpy="0 0 0" />
      <mass value="0" />
      <inertia ixx="0" ixy="0" ixz="0" iyy="0" iyz="0" izz="0" />
    </inertial>
  </link>
  <joint name="radar_joint" type="fixed">
    <origin xyz="0.28945 0 -0.046825" rpy="0 2.8782 0" />
    <parent link="base" />
    <child link="radar" />
    <axis xyz="0 0 0" />
  </joint>

  <link name="arm_base">
    <inertial>
    <origin
        xyz="0 0 0"
        rpy="0 0 0" />
    <mass value="10.162548567403693" />
    <inertia
        ixx="0.000226596924525071"
        ixy="-7.33972270153965E-08"
        ixz="2.13249977802622E-06"
        iyy="0.000269444772561524"
        iyz="8.15169009611054E-09"
        izz="0.000222318258878636" />
    </inertial>
    <visual>
    <origin xyz="0 0 0" rpy="0 0 0" />
    <geometry>
        <mesh filename="../meshes/piper/dae/base_link.dae" />
    </geometry>
    </visual>
    <collision>
        <origin xyz="0 0 0" rpy="0 0 0" />
        <geometry>
            <mesh filename="../meshes/piper/base_link.STL" />
        </geometry>
    </collision>
  </link>
  <joint name="base2arm" type="fixed">
    <origin xyz="0 0 0.06" rpy="0 0 0" />
    <parent link="base" />
    <child link="arm_base" />
    <axis xyz="0 0 0" />
  </joint>

  <link name="link1">
    <inertial>
    <origin
        xyz="0.00131676031927024 0.000310288842008612 -0.00922874512303437"
        rpy="0 0 0" />
    <mass value="0.0978679932242825" />
    <inertia
        ixx="7.76684558296782E-05"
        ixy="1.09084650459924E-07"
        ixz="-1.9748053243241E-06"
        iyy="9.24967780161547E-05"
        iyz="9.91284646834582E-07"
        izz="8.24589062407807E-05" />
    </inertial>
    <visual>
    <origin xyz="0 0 0" rpy="0 0 0" />
    <geometry>
        <mesh filename="../meshes/piper/dae/link1.dae" />
    </geometry>
    </visual>
    <collision>
        <origin xyz="0 0 0" rpy="0 0 1.5708" />
        <geometry>
            <mesh filename="../meshes/piper/link1.STL" />
        </geometry>
    </collision>
  </link>
  <joint name="joint1" type="revolute">
    <origin xyz="0 0 0.123" rpy="0 0 -1.5708" />
    <parent link="arm_base" />
    <child link="link1" />
    <axis xyz="0 0 1" />
    <limit lower="-2.618" upper="2.618" effort="100" velocity="3" />
  </joint>
  <link name="link2">
    <inertial>
    <origin
        xyz="0.148793602378802 -0.00242026983944119 0.00175154638467948"
        rpy="0 0 0" />
    <mass value="0.290888938633388" />
    <inertia
        ixx="0.000148959640166183"
        ixy="-7.37750384371657E-05"
        ixz="-9.68688405196236E-07"
        iyy="0.00172800946632652"
        iyz="-1.09692225564224E-06"
        izz="0.0017754628344594" />
    </inertial>
    <visual>
    <origin xyz="0 0 0" rpy="0 0 0" />
    <geometry>
        <mesh filename="../meshes/piper/dae/link2.dae" />
    </geometry>
    </visual>
    <collision>
        <origin xyz="0 0 0" rpy="0 0 0.1" />
        <geometry>
            <mesh filename="../meshes/piper/link2.STL" />
        </geometry>
    </collision>
  </link>
  <joint name="joint2" type="revolute">
    <origin xyz="0 0 0" rpy="1.5708 -0.034907 -1.5708" />
    <parent link="link1" />
    <child link="link2" />
    <axis xyz="0 0 1" />
    <limit lower="0" upper="3.14" effort="100" velocity="3" />
  </joint>
  <link name="link3">
    <inertial>
    <origin
        xyz="-0.0996835215213704 0.0349477226691318 0.000508025815507312"
        rpy="0 0 0" />
    <mass value="0.290847697793211" />
    <inertia
        ixx="0.000107879011637167"
        ixy="2.92669521203626E-05"
        ixz="6.825922326238E-07"
        iyy="0.000214751671792086"
        iyz="-7.78469047878196E-07"
        izz="0.000241923439340319" />
    </inertial>
    <visual>
    <origin xyz="0 0 0" rpy="0 0 0" />
    <geometry>
        <mesh filename="../meshes/piper/dae/link3.dae" />
    </geometry>
    </visual>
    <collision>
    <origin xyz="0 0 0" rpy="0 0 -1.75" />
    <geometry>
        <mesh filename="../meshes/piper/link3.STL" />
    </geometry>
    </collision>
  </link>
  <joint name="joint3" type="revolute">
    <origin xyz="0.28358 0.028726 0" rpy="0 0 0.06604341" />
    <parent link="link2" />
    <child link="link3" />
    <axis xyz="0 0 1" />
    <limit lower="-2.697" upper="0" effort="100" velocity="3" />
  </joint>
  <link name="link4">
    <inertial>
    <origin
        xyz="0.000276464622387979 -0.00102803669324875 -0.00472830700561663"
        rpy="0 0 0" />
    <mass value="0.127087348341362" />
    <inertia
        ixx="3.82011730423416E-05"
        ixy="-4.92358350897513E-08"
        ixz="4.89589432973119E-08"
        iyy="4.87048555222578E-05"
        iyz="6.70802942500512E-08"
        izz="4.10592077565559E-05" />
    </inertial>
    <visual>
    <origin xyz="0 0 0" rpy="0 0 0" />
    <geometry>
        <mesh filename="../meshes/piper/dae/link4.dae" />
    </geometry>
    </visual>
    <collision>
    <origin xyz="0 0 0" rpy="0 0 0" />
    <geometry>
        <mesh filename="../meshes/piper/link4.STL" />
    </geometry>
    </collision>
  </link>
  <joint name="joint4" type="revolute">
    <origin xyz="-0.24221 0.068514 0" rpy="-1.5708 0 1.3826" />
    <parent link="link3" />
    <child link="link4" />
    <axis xyz="0 0 1" />
    <limit lower="-1.832" upper="1.832" effort="100" velocity="3" />
  </joint>
  <link name="link5">
    <inertial>
    <origin
        xyz="8.82262433516967E-05 0.0566829014808256 -0.00196119720482461"
        rpy="0 0 0" />
    <mass value="0.144711242639457" />
    <inertia
        ixx="4.39644313662493E-05"
        ixy="-3.59259686444846E-08"
        ixz="-1.89747741386183E-08"
        iyy="5.63173920951307E-05"
        iyz="-2.1540716689785E-07"
        izz="4.88713664675268E-05" />
    </inertial>
    <visual>
    <origin xyz="0 0 0" rpy="0 0 0" />
    <geometry>
        <mesh filename="../meshes/piper/dae/link5.dae" />
    </geometry>
    </visual>
    <collision>
    <origin xyz="0 0 0" rpy="0 0 -3.14" />
    <geometry>
        <mesh filename="../meshes/piper/link5.STL" />
    </geometry>
    </collision>
  </link>
  <joint name="joint5" type="revolute">
    <origin xyz="0 0 0" rpy="1.5708 0 0" />
    <parent link="link4" />
    <child link="link5" />
    <axis xyz="0 0 1" />
    <limit lower="-1.22" upper="1.22" effort="100" velocity="3" />
  </joint>
  <link name="link6">
    <inertial>
    <origin
        xyz="0.00103120214523473 0.0121761387587524 0.0315480874960164"
        rpy="0 0 0" />
    <mass value="0.195187143240719" />
    <inertia
        ixx="6.43790256535539E-05"
        ixy="-1.2366166157046E-06"
        ixz="1.97664606328472E-07"
        iyy="0.000126146396374301"
        iyz="2.41157078516408E-06"
        izz="0.000154087076816444" />
    </inertial>
    <visual>
    <origin xyz="-0.002 -0.008 0" rpy="-1.57 0 0" />
    <geometry>
        <mesh filename="../meshes/piper/dae/camera_v3.dae"/>
    </geometry>
    </visual>
    <collision>
    <origin xyz="-0.002 -0.008 0" rpy="-1.57 0 0" />
    <geometry>
        <mesh filename="../meshes/piper/dae/camera_v3.dae"/>
    </geometry>
    </collision>
  </link>
  <joint name="joint6" type="revolute">
    <origin xyz="0 0.091 0.0014165" rpy="-1.5708 -1.5708 0" />
    <parent link="link5" />
    <child link="link6" />
    <axis xyz="0 0 1" />
    <limit lower="-3.14" upper="3.14" effort="100" velocity="3" />
  </joint>
  <link name="link7">
    <inertial>
    <origin
        xyz="-0.000277778383727112 -0.0467673043650824 -0.00921029491873201"
        rpy="0 0 0" />
    <mass value="0.02648229234527" />
    <inertia
        ixx="9.99787479924589E-06"
        ixy="-1.57548495096104E-07"
        ixz="-2.71342775003487E-08"
        iyy="6.1795212293655E-06"
        iyz="-1.58939803580081E-06"
        izz="1.42102717246564E-05" />
    </inertial>
    <visual>
    <origin xyz="0 0 0" rpy="0 0 0" />
    <geometry>
        <mesh filename="../meshes/piper/dae/link7.dae" />
    </geometry>
    </visual>
    <collision>
    <origin xyz="-0.001 0 0.0003" rpy="0 3.14 0" />
    <geometry>
        <mesh filename="../meshes/piper/link7.STL" />
    </geometry>
    </collision>
  </link>
  <joint name="joint7" type="fixed" dont_collapse="true">
    <origin xyz="0 0 0.13503" rpy="1.5708 0 1.5708" />
    <parent link="link6" />
    <child link="link7" />
    <axis xyz="0 0 -1" />
    <limit lower="0" upper="0.05" effort="100" velocity="1" />
  </joint>
  <link name="link8">
    <inertial>
    <origin
        xyz="0.000277816920932317 0.0467673824063769 -0.00921030054508036"
        rpy="0 0 0" />
    <mass value="0.0264822021416248" />
    <inertia
        ixx="9.99779119357223E-06"
        ixy="-1.57542283433504E-07"
        ixz="2.71367446701359E-08"
        iyy="6.17952441557932E-06"
        iyz="1.58939319453383E-06"
        izz="1.4210192754512E-05" />
    </inertial>
    <visual>
    <origin xyz="0 0 0" rpy="0 0 0" />
    <geometry>
        <mesh filename="../meshes/piper/dae/link8.dae" />
    </geometry>
    </visual>
    <collision>
    <origin xyz="-0.001 0 0.0003" rpy="3.14 0 0" />
    <geometry>
        <mesh filename="../meshes/piper/link8.STL" />
    </geometry>
    </collision>
  </link>
  <joint name="joint8" type="fixed" dont_collapse="true">
    <origin xyz="0 0 0.13503" rpy="-1.5708 0 1.5708" />
    <parent link="link6" />
    <child link="link8" />
    <axis xyz="0 0 1" />
    <limit lower="-0.05" upper="0" effort="100" velocity="1" />
  </joint>

  <link name="hand_cam">
    <inertial>
      <origin
        xyz="0.0009804 0.025556 -0.036977"
        rpy="0 0 0" />
      <mass
        value="0.0067926" />
      <inertia
        ixx="3.7811E-05"
        ixy="2.2861E-18"
        ixz="2.2446E-19"
        iyy="9.4061E-05"
        iyz="6.1172E-06"
        izz="0.00012345" />
    </inertial>
    <visual>
      <origin
        xyz="0 0 0"
        rpy="0 0 0" />
      <geometry>
          <box size="0.02 0.05 0.02"/>
      </geometry>
    </visual>
    <collision>
      <origin
        xyz="0 0 0"
        rpy="0 1.57 0" />
      <geometry>
        <box size="0.001 0.001 0.001"/>
      </geometry>
    </collision>
  </link>
  <joint name="hand_camera_joint" type="fixed">
    <origin
    xyz="0.0 0.075 0.03"
    rpy="0 -0.3 1.57 " />
    <parent
    link="link6" />
    <child
    link="hand_cam" />
    <axis
    xyz="0 0 0" />
  </joint>

</robot>