<?xml version='1.0' encoding='utf-8'?>
<robot name="go2w_piper_description">

  <link name="base">
    <inertial>
      <origin xyz="0.021112 0 -0.005366" rpy="0 0 0" />
      <mass value="6.921" />
      <inertia ixx="0.02448" ixy="0.00012166" ixz="0.0014849" iyy="0.098077" iyz="-3.12E-05" izz="0.107" />
    </inertial>
    <visual>
      <origin xyz="0 0 0" rpy="0 0 0" />
      <geometry>
        <mesh filename="../meshes/go2w/base.dae" />
      </geometry>
      <material name="深色橡胶_001-effect"><color rgba="0.6717055 0.6924257 0.7742702 1" /></material><material name="白色logo_001-effect"><color rgba="1 1 1 1" /></material><material name="黑色贴纸_007-effect"><color rgba="0.009018 0.009018 0.009018 1" /></material><material name="黑色金属_007-effect"><color rgba="0.01341 0.01341 0.01341 1" /></material><material name="黑色塑料_003-effect"><color rgba="0.023455 0.023455 0.023455 1" /></material></visual>
    <collision>
      <origin rpy="0 0 0" xyz="0 0 0" />
      <geometry>
        <box size="0.3762 0.0935 0.114" />
      </geometry>
    </collision>
  </link>

  <link name="FL_hip">
    <inertial>
      <origin xyz="-0.0054 0.00194 -0.000105" rpy="0 0 0" />
      <mass value="0.678" />
      <inertia ixx="0.00048" ixy="-3.01E-06" ixz="1.11E-06" iyy="0.000884" iyz="-1.42E-06" izz="0.000596" />
    </inertial>
    <visual>
      <origin xyz="0 0 0" rpy="0 0 0" />
      <geometry>
        <mesh filename="../meshes/go2w/hip.dae" />
      </geometry>
      <material name="深色橡胶_001-effect"><color rgba="0.6717055 0.6924257 0.7742702 1" /></material><material name="Material-effect"><color rgba="0.9 0.95 0.95 1" /></material></visual>
    <collision>
      <origin rpy="1.5707963267948966 0 0" xyz="0 0.08 0" />
      <geometry>
        <cylinder length="0.04" radius="0.046" />
      </geometry>
    </collision>
  </link>
  <joint name="FL_hip_joint" type="revolute">
    <origin xyz="0.1934 0.0465 0" rpy="0 0 0" />
    <parent link="base" />
    <child link="FL_hip" />
    <axis xyz="1 0 0" />
    <limit lower="-1.0472" upper="1.0472" effort="23.7" velocity="30.1" />
  </joint>
  <link name="FL_thigh">
    <inertial>
      <origin xyz="-0.00374 -0.0223 -0.0327" rpy="0 0 0" />
      <mass value="1.152" />
      <inertia ixx="0.00584" ixy="8.72E-05" ixz="-0.000289" iyy="0.0058" iyz="0.000808" izz="0.00103" />
    </inertial>
    <visual>
      <origin xyz="0 0 0" rpy="0 0 0" />
      <geometry>
        <mesh filename="../meshes/go2w/thigh.dae" />
      </geometry>
      <material name="深色橡胶_003-effect"><color rgba="0.6717055 0.6924257 0.7742702 1" /></material><material name="Material_009-effect"><color rgba="0.9 0.95 0.95 1" /></material></visual>
    <collision>
      <origin rpy="0 1.5707963267948966 0" xyz="0 0 -0.1065" />
      <geometry>
        <box size="0.11 0.0245 0.034" />
      </geometry>
    </collision>
  </link>
  <joint name="FL_thigh_joint" type="revolute">
    <origin xyz="0 0.0955 0" rpy="0 0 0" />
    <parent link="FL_hip" />
    <child link="FL_thigh" />
    <axis xyz="0 1 0" />
    <limit lower="-1.5707963267948966" upper="3.4907" effort="23.7" velocity="30.1" />
  </joint>
  <link name="FL_calf">
    <inertial>
      <origin xyz="0.00548 -0.000975 -0.115" rpy="0 0 0" />
      <mass value="0.154" />
      <inertia ixx="0.00108" ixy="3.4E-07" ixz="1.72E-05" iyy="0.0011" iyz="8.28E-06" izz="3.29E-05" />
    </inertial>
    <visual>
      <origin xyz="0 0 0" rpy="-1.5707963267948966 0 0" />
      <geometry>
        <mesh filename="../meshes/go2w/calf.stl" />
      </geometry>
      <material name="">
        <color rgba="1 1 1 1" />
      </material>
    </visual>
    <collision>
      <origin rpy="0 -0.21 0" xyz="0.008 0 -0.06" />
      <geometry>
        <cylinder length="0.12" radius="0.012" />
      </geometry>
    </collision>
  </link>
  <joint name="FL_calf_joint" type="revolute">
    <origin xyz="0 0 -0.213" rpy="0 0 0" />
    <parent link="FL_thigh" />
    <child link="FL_calf" />
    <axis xyz="0 1 0" />
    <limit lower="-2.7227" upper="-0.83776" effort="35.55" velocity="20.07" />
  </joint>
  <link name="FL_calflower">
    <collision>
      <origin rpy="0 0 0" xyz="0 0 0" />
      <geometry>
        <cylinder length="0.065" radius="0.011" />
      </geometry>
    </collision>
  </link>
  <joint name="FL_calflower_joint" type="fixed">
    <origin xyz="0.020 0 -0.148" rpy="0 0.05 0" />
    <parent link="FL_calf" />
    <child link="FL_calflower" />
    <axis xyz="0 0 0" />
  </joint>
  <link name="FL_calflower1">
    <collision>
      <origin rpy="0 0 0" xyz="0 0 0" />
      <geometry>
        <cylinder length="0.03" radius="0.0155" />
      </geometry>
    </collision>
  </link>
  <joint name="FL_calflower1_joint" type="fixed">
    <origin xyz="-0.01 0 -0.04" rpy="0 0.48 0" />
    <parent link="FL_calflower" />
    <child link="FL_calflower1" />
    <axis xyz="0 0 0" />
  </joint>
  <link name="FL_foot_motor">
    <inertial>
      <origin xyz="0 0.0 0" rpy="0 0 0" />
      <mass value="0.646" />
      <inertia ixx="0.001" ixy="0" ixz="0" iyy="0.0016" iyz="0" izz="0.001" />
    </inertial>
    <collision>
      <origin rpy="1.5707963267948966 0 0" xyz="0 0 0" />
      <geometry>
        <cylinder length="0.05" radius="0.05" />
      </geometry>
    </collision>
  </link>
  <joint name="FL_foot_motor_joint" type="fixed">
    <origin xyz="-0.00 0.01 -0.2264" rpy="0 0.0 0" />
    <parent link="FL_calf" />
    <child link="FL_foot_motor" />
    <axis xyz="0 0 0" />
  </joint>
  <link name="FL_foot">
    <inertial>
      <origin xyz="0 0.06 0" rpy="0 0 0" />
      <mass value="0.520" />
      <inertia ixx="0.0007" ixy="0" ixz="0" iyy="0.0012" iyz="0" izz="0.0007" />
    </inertial>
    <visual>
      <origin xyz="0 0 0" rpy="0 0 0" />
      <geometry>
        <mesh filename="../meshes/go2w/left_wheel.dae" />
      </geometry>
      <material name="">
        <color rgba="1 1 1 1" />
      </material>
    </visual>
    <collision>
      <origin rpy="1.5707963267948966 0 0" xyz="0 0.048 0" />
      <geometry>
        <cylinder length="0.048" radius="0.086" />
      </geometry>
    </collision>
  </link>
  <joint name="FL_foot_joint" type="revolute">
    <origin xyz="0 0 -0.2264" rpy="0 0 0" />
    <parent link="FL_calf" />
    <child link="FL_foot" />
    <axis xyz="0 1 0" />
    <limit effort="23.7" velocity="30.1" />
  </joint>
  
  <link name="FR_hip">
    <inertial>
      <origin xyz="-0.0054 -0.00194 -0.000105" rpy="0 0 0" />
      <mass value="0.678" />
      <inertia ixx="0.00048" ixy="3.01E-06" ixz="1.11E-06" iyy="0.000884" iyz="1.42E-06" izz="0.000596" />
    </inertial>
    <visual>
      <origin xyz="0 0 0" rpy="3.1415 0 0" />
      <geometry>
        <mesh filename="../meshes/go2w/hip.dae" />
      </geometry>
      <material name="深色橡胶_001-effect"><color rgba="0.6717055 0.6924257 0.7742702 1" /></material><material name="Material-effect"><color rgba="0.9 0.95 0.95 1" /></material></visual>
    <collision>
      <origin rpy="1.5707963267948966 0 0" xyz="0 -0.08 0" />
      <geometry>
        <cylinder length="0.04" radius="0.046" />
      </geometry>
    </collision>
  </link>
  <joint name="FR_hip_joint" type="revolute">
    <origin xyz="0.1934 -0.0465 0" rpy="0 0 0" />
    <parent link="base" />
    <child link="FR_hip" />
    <axis xyz="1 0 0" />
    <limit lower="-1.0472" upper="1.0472" effort="23.7" velocity="30.1" />
  </joint>
  <link name="FR_thigh">
    <inertial>
      <origin xyz="-0.00374 0.0223 -0.0327" rpy="0 0 0" />
      <mass value="1.152" />
      <inertia ixx="0.00584" ixy="-8.72E-05" ixz="-0.000289" iyy="0.0058" iyz="-0.000808" izz="0.00103" />
    </inertial>
    <visual>
      <origin xyz="0 0 0" rpy="0 0 0" />
      <geometry>
        <mesh filename="../meshes/go2w/thigh_mirror.dae" />
      </geometry>
      <material name="深色橡胶_012-effect"><color rgba="0.6717055 0.6924257 0.7742702 1" /></material><material name="Material_011-effect"><color rgba="0.9 0.95 0.95 1" /></material></visual>
    <collision>
      <origin rpy="0 1.5707963267948966 0" xyz="0 0 -0.1065" />
      <geometry>
        <box size="0.11 0.0245 0.034" />
      </geometry>
    </collision>
  </link>
  <joint name="FR_thigh_joint" type="revolute">
    <origin xyz="0 -0.0955 0" rpy="0 0 0" />
    <parent link="FR_hip" />
    <child link="FR_thigh" />
    <axis xyz="0 1 0" />
    <limit lower="-1.5707963267948966" upper="3.4907" effort="23.7" velocity="30.1" />
  </joint>
  <link name="FR_calf">
    <inertial>
      <origin xyz="0.00548 0.000975 -0.115" rpy="0 0 0" />
      <mass value="0.154" />
      <inertia ixx="0.00108" ixy="-3.4E-07" ixz="1.72E-05" iyy="0.0011" iyz="-8.28E-06" izz="3.29E-05" />
    </inertial>
    <visual>
      <origin xyz="0 0 0" rpy="-1.5707963267948966 0 0" />
      <geometry>
        <mesh filename="../meshes/go2w/calf_mirror.stl" />
      </geometry>
      <material name="">
        <color rgba="1 1 1 1" />
      </material>
    </visual>
    <collision>
      <origin rpy="0 -0.2 0" xyz="0.01 0 -0.06" />
      <geometry>
        <cylinder length="0.12" radius="0.013" />
      </geometry>
    </collision>
  </link>
  <joint name="FR_calf_joint" type="revolute">
    <origin xyz="0 0 -0.213" rpy="0 0 0" />
    <parent link="FR_thigh" />
    <child link="FR_calf" />
    <axis xyz="0 1 0" />
    <limit lower="-2.7227" upper="-0.83776" effort="35.55" velocity="20.07" />
  </joint>
  <link name="FR_calflower">
    <collision>
      <origin rpy="0 0 0" xyz="0 0 0" />
      <geometry>
        <cylinder length="0.065" radius="0.011" />
      </geometry>
    </collision>
  </link>
  <joint name="FR_calflower_joint" type="fixed">
    <origin xyz="0.020 0 -0.148" rpy="0 0.05 0" />
    <parent link="FR_calf" />
    <child link="FR_calflower" />
    <axis xyz="0 0 0" />
  </joint>
  <link name="FR_calflower1">
    <collision>
      <origin rpy="0 0 0" xyz="0 0 0" />
      <geometry>
        <cylinder length="0.03" radius="0.0155" />
      </geometry>
    </collision>
  </link>
  <joint name="FR_calflower1_joint" type="fixed">
    <origin xyz="-0.01 0 -0.04" rpy="0 0.48 0" />
    <parent link="FR_calflower" />
    <child link="FR_calflower1" />
    <axis xyz="0 0 0" />
  </joint>
  <link name="FR_foot_motor">
    <inertial>
      <origin xyz="0 0.0 0" rpy="0 0 0" />
      <mass value="0.646" />
      <inertia ixx="0.001" ixy="0" ixz="0" iyy="0.0016" iyz="0" izz="0.001" />
    </inertial>
    <collision>
      <origin rpy="1.5707963267948966 0 0" xyz="0 0 0" />
      <geometry>
        <cylinder length="0.05" radius="0.05" />
      </geometry>
    </collision>
  </link>
  <joint name="FR_foot_motor_joint" type="fixed">
    <origin xyz="0.0 -0.01 -0.2264" rpy="0 0.0 0" />
    <parent link="FR_calf" />
    <child link="FR_foot_motor" />
    <axis xyz="0 0 0" />
  </joint>
  <link name="FR_foot">
    <inertial>
      <origin xyz="0 -0.06 0" rpy="0 0 0" />
      <mass value="0.520" />
      <inertia ixx="0.0007" ixy="0" ixz="0" iyy="0.0012" iyz="0" izz="0.0007" />
    </inertial>
    <visual>
      <origin xyz="0 0 0" rpy="0 0 0" />
      <geometry>
        <mesh filename="../meshes/go2w/right_wheel.dae" />
      </geometry>
      <material name="">
        <color rgba="1 1 1 1" />
      </material>
    </visual>
    <collision>
      <origin rpy="1.5707963267948966 0 0" xyz="0 -0.048 0" />
      <geometry>
        <cylinder length="0.048" radius="0.086" />
      </geometry>
    </collision>
  </link>
  <joint name="FR_foot_joint" type="revolute">
    <origin xyz="0 0 -0.2264" rpy="0 0 0" />
    <parent link="FR_calf" />
    <child link="FR_foot" />
    <axis xyz="0 1 0" />
    <limit effort="23.7" velocity="30.1" />
  </joint>

  <link name="RL_hip">
    <inertial>
      <origin xyz="0.0054 0.00194 -0.000105" rpy="0 0 0" />
      <mass value="0.678" />
      <inertia ixx="0.00048" ixy="3.01E-06" ixz="-1.11E-06" iyy="0.000884" iyz="-1.42E-06" izz="0.000596" />
    </inertial>
    <visual>
      <origin xyz="0 0 0" rpy="0 3.1415 0" />
      <geometry>
        <mesh filename="../meshes/go2w/hip.dae" />
      </geometry>
      <material name="深色橡胶_001-effect"><color rgba="0.6717055 0.6924257 0.7742702 1" /></material><material name="Material-effect"><color rgba="0.9 0.95 0.95 1" /></material></visual>
    <collision>
      <origin rpy="1.5707963267948966 0 0" xyz="0 0.08 0" />
      <geometry>
        <cylinder length="0.04" radius="0.046" />
      </geometry>
    </collision>
  </link>
  <joint name="RL_hip_joint" type="revolute">
    <origin xyz="-0.1934 0.0465 0" rpy="0 0 0" />
    <parent link="base" />
    <child link="RL_hip" />
    <axis xyz="1 0 0" />
    <limit lower="-1.0472" upper="1.0472" effort="23.7" velocity="30.1" />
  </joint>
  <link name="RL_thigh">
    <inertial>
      <origin xyz="-0.00374 -0.0223 -0.0327" rpy="0 0 0" />
      <mass value="1.152" />
      <inertia ixx="0.00584" ixy="8.72E-05" ixz="-0.000289" iyy="0.0058" iyz="0.000808" izz="0.00103" />
    </inertial>
    <visual>
      <origin xyz="0 0 0" rpy="0 0 0" />
      <geometry>
        <mesh filename="../meshes/go2w/thigh.dae" />
      </geometry>
      <material name="深色橡胶_003-effect"><color rgba="0.6717055 0.6924257 0.7742702 1" /></material><material name="Material_009-effect"><color rgba="0.9 0.95 0.95 1" /></material></visual>
    <collision>
      <origin rpy="0 1.5707963267948966 0" xyz="0 0 -0.1065" />
      <geometry>
        <box size="0.11 0.0245 0.034" />
      </geometry>
    </collision>
  </link>
  <joint name="RL_thigh_joint" type="revolute">
    <origin xyz="0 0.0955 0" rpy="0 0 0" />
    <parent link="RL_hip" />
    <child link="RL_thigh" />
    <axis xyz="0 1 0" />
    <limit lower="-0.5236" upper="4.5379" effort="23.7" velocity="30.1" />
  </joint>
  <link name="RL_calf">
    <inertial>
      <origin xyz="0.00548 -0.000975 -0.115" rpy="0 0 0" />
      <mass value="0.154" />
      <inertia ixx="0.00108" ixy="3.4E-07" ixz="1.72E-05" iyy="0.0011" iyz="8.28E-06" izz="3.29E-05" />
    </inertial>
    <visual>
      <origin xyz="0 0 0" rpy="-1.5707963267948966 0 0" />
      <geometry>
        <mesh filename="../meshes/go2w/calf.stl" />
      </geometry>
      <material name="">
        <color rgba="1 1 1 1" />
      </material>
    </visual>
    <collision>
      <origin rpy="0 -0.2 0" xyz="0.01 0 -0.06" />
      <geometry>
        <cylinder length="0.12" radius="0.013" />
      </geometry>
    </collision>
  </link>
  <joint name="RL_calf_joint" type="revolute">
    <origin xyz="0 0 -0.213" rpy="0 0 0" />
    <parent link="RL_thigh" />
    <child link="RL_calf" />
    <axis xyz="0 1 0" />
    <limit lower="-2.7227" upper="-0.83776" effort="35.55" velocity="20.07" />
  </joint>
  <link name="RL_calflower">
    <collision>
      <origin rpy="0 0 0" xyz="0 0 0" />
      <geometry>
        <cylinder length="0.065" radius="0.011" />
      </geometry>
    </collision>
  </link>
  <joint name="RL_calflower_joint" type="fixed">
    <origin xyz="0.020 0 -0.148" rpy="0 0.05 0" />
    <parent link="RL_calf" />
    <child link="RL_calflower" />
    <axis xyz="0 0 0" />
  </joint>
  <link name="RL_calflower1">
    <collision>
      <origin rpy="0 0 0" xyz="0 0 0" />
      <geometry>
        <cylinder length="0.03" radius="0.0155" />
      </geometry>
    </collision>
  </link>
  <joint name="RL_calflower1_joint" type="fixed">
    <origin xyz="-0.01 0 -0.04" rpy="0 0.48 0" />
    <parent link="RL_calflower" />
    <child link="RL_calflower1" />
    <axis xyz="0 0 0" />
  </joint>
  <link name="RL_foot_motor">
    <inertial>
        <origin xyz="0 0.0 0" rpy="0 0 0" />
        <mass value="0.646" />
        <inertia ixx="0.001" ixy="0" ixz="0" iyy="0.0016" iyz="0" izz="0.001" />
    </inertial>
    <collision>
        <origin rpy="1.5707963267948966 0 0" xyz="0 0 0" />
        <geometry>
        <cylinder length="0.05" radius="0.05" />
        </geometry>
    </collision>
  </link>
  <joint name="RL_foot_motor_joint" type="fixed">
    <origin xyz="0.00 0.01 -0.2264" rpy="0 0.0 0" />
    <parent link="RL_calf" />
    <child link="RL_foot_motor" />
    <axis xyz="0 0 0" />
  </joint>
  <link name="RL_foot">
    <inertial>
      <origin xyz="0 0.06 0" rpy="0 0 0" />
      <mass value="0.520" />
      <inertia ixx="0.0007" ixy="0" ixz="0" iyy="0.0012" iyz="0" izz="0.0007" />
    </inertial>
    <visual>
      <origin xyz="0 0 0" rpy="0 0 0" />
      <geometry>
        <mesh filename="../meshes/go2w/left_wheel.dae" />
      </geometry>
      <material name="">
        <color rgba="1 1 1 1" />
      </material>
    </visual>
    <collision>
      <origin rpy="1.5707963267948966 0 0" xyz="0 0.048 0" />
      <geometry>
        <cylinder length="0.048" radius="0.086" />
      </geometry>
    </collision>
  </link>
  <joint name="RL_foot_joint" type="revolute">
    <origin xyz="0.0 0 -0.2264" rpy="0 0 0" />
    <parent link="RL_calf" />
    <child link="RL_foot" />
    <axis xyz="0 1 0" />
    <limit effort="23.7" velocity="30.1" />
  </joint>

  <link name="RR_hip">
    <inertial>
      <origin xyz="0.0054 -0.00194 -0.000105" rpy="0 0 0" />
      <mass value="0.678" />
      <inertia ixx="0.00048" ixy="-3.01E-06" ixz="-1.11E-06" iyy="0.000884" iyz="1.42E-06" izz="0.000596" />
    </inertial>
    <visual>
      <origin xyz="0 0 0" rpy="3.1415 3.1415 0" />
      <geometry>
        <mesh filename="../meshes/go2w/hip.dae" />
      </geometry>
      <material name="深色橡胶_001-effect"><color rgba="0.6717055 0.6924257 0.7742702 1" /></material><material name="Material-effect"><color rgba="0.9 0.95 0.95 1" /></material></visual>
    <collision>
      <origin rpy="1.5707963267948966 0 0" xyz="0 -0.08 0" />
      <geometry>
        <cylinder length="0.04" radius="0.046" />
      </geometry>
    </collision>
  </link>
  <joint name="RR_hip_joint" type="revolute">
    <origin xyz="-0.1934 -0.0465 0" rpy="0 0 0" />
    <parent link="base" />
    <child link="RR_hip" />
    <axis xyz="1 0 0" />
    <limit lower="-1.0472" upper="1.0472" effort="23.7" velocity="30.1" />
  </joint>
  <link name="RR_thigh">
    <inertial>
      <origin xyz="-0.00374 0.0223 -0.0327" rpy="0 0 0" />
      <mass value="1.152" />
      <inertia ixx="0.00584" ixy="-8.72E-05" ixz="-0.000289" iyy="0.0058" iyz="-0.000808" izz="0.00103" />
    </inertial>
    <visual>
      <origin xyz="0 0 0" rpy="0 0 0" />
      <geometry>
        <mesh filename="../meshes/go2w/thigh_mirror.dae" />
      </geometry>
      <material name="深色橡胶_012-effect"><color rgba="0.6717055 0.6924257 0.7742702 1" /></material><material name="Material_011-effect"><color rgba="0.9 0.95 0.95 1" /></material></visual>
    <collision>
      <origin rpy="0 1.5707963267948966 0" xyz="0 0 -0.1065" />
      <geometry>
        <box size="0.11 0.0245 0.034" />
      </geometry>
    </collision>
  </link>
  <joint name="RR_thigh_joint" type="revolute">
    <origin xyz="0 -0.0955 0" rpy="0 0 0" />
    <parent link="RR_hip" />
    <child link="RR_thigh" />
    <axis xyz="0 1 0" />
    <limit lower="-0.5236" upper="4.5379" effort="23.7" velocity="30.1" />
  </joint>
  <link name="RR_calf">
    <inertial>
      <origin xyz="0.00548 0.000975 -0.115" rpy="0 0 0" />
      <mass value="0.154" />
      <inertia ixx="0.00108" ixy="-3.4E-07" ixz="1.72E-05" iyy="0.0011" iyz="-8.28E-06" izz="3.29E-05" />
    </inertial>
    <visual>
      <origin xyz="0 0 0" rpy="-1.5707963267948966 0 0" />
      <geometry>
        <mesh filename="../meshes/go2w/calf_mirror.stl" />
      </geometry>
      <material name="">
        <color rgba="1 1 1 1" />
      </material>
    </visual>
    <collision>
      <origin rpy="0 -0.2 0" xyz="0.01 0 -0.06" />
      <geometry>
        <cylinder length="0.12" radius="0.013" />
      </geometry>
    </collision>
  </link>
  <joint name="RR_calf_joint" type="revolute">
    <origin xyz="0 0 -0.213" rpy="0 0 0" />
    <parent link="RR_thigh" />
    <child link="RR_calf" />
    <axis xyz="0 1 0" />
    <limit lower="-2.7227" upper="-0.83776" effort="35.55" velocity="20.07" />
  </joint>
  <link name="RR_calflower">
    <collision>
      <origin rpy="0 0 0" xyz="0 0 0" />
      <geometry>
        <cylinder length="0.065" radius="0.011" />
      </geometry>
    </collision>
  </link>
  <joint name="RR_calflower_joint" type="fixed">
    <origin xyz="0.020 0 -0.148" rpy="0 0.05 0" />
    <parent link="RR_calf" />
    <child link="RR_calflower" />
    <axis xyz="0 0 0" />
  </joint>
  <link name="RR_calflower1">
    <collision>
      <origin rpy="0 0 0" xyz="0 0 0" />
      <geometry>
        <cylinder length="0.03" radius="0.0155" />
      </geometry>
    </collision>
  </link>
  <joint name="RR_calflower1_joint" type="fixed">
    <origin xyz="-0.01 0 -0.04" rpy="0 0.48 0" />
    <parent link="RR_calflower" />
    <child link="RR_calflower1" />
    <axis xyz="0 0 0" />
  </joint>
  <link name="RR_foot_motor">
    <inertial>
        <origin xyz="0 0.0 0" rpy="0 0 0" />
        <mass value="0.646" />
        <inertia ixx="0.001" ixy="0" ixz="0" iyy="0.0016" iyz="0" izz="0.001" />
    </inertial>
    <collision>
        <origin rpy="1.5707963267948966 0 0" xyz="0 0 0" />
        <geometry>
        <cylinder length="0.05" radius="0.05" />
        </geometry>
    </collision>
  </link>
  <joint name="RR_foot_motor_joint" type="fixed">
    <origin xyz="0.00 -0.01 -0.2264" rpy="0 0.0 0" />
    <parent link="RR_calf" />
    <child link="RR_foot_motor" />
    <axis xyz="0 0 0" />
  </joint>
  <link name="RR_foot">
    <inertial>
      <origin xyz="0 -0.06 0" rpy="0 0 0" />
      <mass value="0.520" />
      <inertia ixx="0.0007" ixy="0" ixz="0" iyy="0.0012" iyz="0" izz="0.0007" />
    </inertial>
    <visual>
      <origin xyz="0 0 0" rpy="0 0 0" />
      <geometry>
        <mesh filename="../meshes/go2w/right_wheel.dae" />
      </geometry>
      <material name="">
        <color rgba="1 1 1 1" />
      </material>
    </visual>
    <collision>
      <origin rpy="1.5707963267948966 0 0" xyz="0 -0.048 0" />
      <geometry>
        <cylinder length="0.048" radius="0.086" />
      </geometry>
    </collision>
  </link>
  <joint name="RR_foot_joint" type="revolute">
    <origin xyz="-0.0 0 -0.2264" rpy="0 0 0" />
    <parent link="RR_calf" />
    <child link="RR_foot" />
    <axis xyz="0 1 0" />
    <limit effort="23.7" velocity="30.1" />
  </joint>

  <link
    name="arm_base">
    <inertial>
      <origin 
        xyz="-0.00473641164191482 2.56829134630247E-05 0.041451518036016" 
        rpy="0 0 0" />
      <mass 
        value="1.02" />
      <inertia 
        ixx="0.00267433" 
        ixy="-0.00000073" 
        ixz="-0.00017389" 
        iyy="0.00282612" 
        iyz="0.0000004" 
        izz="0.00089624" />
    </inertial>
    <visual>
      <origin
        xyz="0 0 0"
        rpy="-1.5707963267948966 0 0" />
      <geometry>
        <mesh
          filename="../meshes/piper/base_link.STL" />
      </geometry>
      <material
        name="">
        <color
          rgba="0.792156862745098 0.819607843137255 0.933333333333333 1" />
      </material>
    </visual>
    <collision>
      <origin
        xyz="0 0 0"
        rpy="0 0 0" />
      <geometry>
        <mesh
          filename="../meshes/piper/base_link.STL" />
      </geometry>
    </collision>
  </link>
  <joint name="base2arm" type="fixed" dont_collapse="true">
    <origin xyz="0 0 0.05" rpy="0 0 0" />
    <parent link="base" />
    <child link="arm_base" />
    <axis xyz="0 0 0" />
  </joint>
  
  <link
    name="link1">
    <inertial>
      <origin 
        xyz="0.000121504734057468 0.000104632162460536 -0.00438597309559853" 
        rpy="0 0 0" />
      <mass 
        value="0.71" />
      <inertia 
        ixx="0.00048916" 
        ixy="-0.00000036" 
        ixz="-0.00000224" 
        iyy="0.00040472" 
        iyz="-0.00000242" 
        izz="0.00043982" />
    </inertial>
    <visual>
      <origin
        xyz="0 0 0"
        rpy="-1.5707963267948966 0 0" />
      <geometry>
        <mesh
          filename="../meshes/piper/link1.STL" />
      </geometry>
      <material
        name="">
        <color
          rgba="0.792156862745098 0.819607843137255 0.933333333333333 1" />
      </material>
    </visual>
    <collision>
      <origin
        xyz="0 0 0"
        rpy="0 0 0" />
      <geometry>
        <mesh
          filename="../meshes/piper/link1.STL" />
      </geometry>
    </collision>
  </link>
  <joint
    name="joint1"
    type="revolute">
    <origin
      xyz="0 0 0.123"
      rpy="0 0 0" />
    <parent
      link="arm_base" />
    <child
      link="link1" />
    <axis
      xyz="0 0 1" />
    <limit
      lower="-2.618"
      upper="2.618"
      effort="100"
      velocity="5" />
  </joint>
  <link
    name="link2">
    <inertial>
      <origin 
        xyz="0.198666145229743 -0.010926924140076 0.00142121714502687" 
        rpy="0 0 0" />
      <mass 
        value="1.17" />
      <inertia 
        ixx="0.00116918" 
        ixy="-0.00180037" 
        ixz="0.00025146" 
        iyy="0.06785384" 
        iyz="-0.00000455" 
        izz="0.06774489" />
    </inertial>
    <visual>
      <origin
        xyz="0 0 0"
        rpy="-1.5707963267948966 0 0" />
      <geometry>
        <mesh
          filename="../meshes/piper/link2.STL" />
      </geometry>
      <material
        name="">
        <color
          rgba="0.792156862745098 0.819607843137255 0.933333333333333 1" />
      </material>
    </visual>
    <collision>
      <origin
        xyz="0 0 0"
        rpy="0 0 0" />
      <geometry>
        <mesh
          filename="../meshes/piper/link2.STL" />
      </geometry>
    </collision>
  </link>
  <joint
    name="joint2"
    type="revolute">
    <origin
      xyz="0 0 0"
      rpy="1.5708 -0.1359 -3.1416" />
    <parent
      link="link1" />
    <child
      link="link2" />
    <axis
      xyz="0 0 1" />
    <limit
      lower="0"
      upper="3.14"
      effort="100"
      velocity="5" />
  </joint>
  <link
    name="link3">
    <inertial>
      <origin 
        xyz="-0.0202737662122021 -0.133914995944595 -0.000458682652737356" 
        rpy="0 0 0" />
      <mass 
        value="0.5" />
      <inertia 
        ixx="0.01361711" 
        ixy="0.00165794" 
        ixz="-0.00000048" 
        iyy="0.00045024" 
        iyz="-0.00000045" 
        izz="0.01380322" />
    </inertial>
    <visual>
      <origin
        xyz="0 0 0"
        rpy="-1.5707963267948966 0 0" />
      <geometry>
        <mesh
          filename="../meshes/piper/link3.STL" />
      </geometry>
      <material
        name="">
        <color
          rgba="0.792156862745098 0.819607843137255 0.933333333333333 1" />
      </material>
    </visual>
    <collision>
      <origin
        xyz="0 0 0"
        rpy="0 0 0" />
      <geometry>
        <mesh
          filename="../meshes/piper/link3.STL" />
      </geometry>
    </collision>
  </link>
  <joint
    name="joint3"
    type="revolute">
    <origin
      xyz="0.28503 0 0"
      rpy="0 0 -1.7939" />
    <parent
      link="link2" />
    <child
      link="link3" />
    <axis
      xyz="0 0 1" />
    <limit
      lower="-2.967"
      upper="0"
      effort="100"
      velocity="5" />
  </joint>
  <link
    name="link4">
    <inertial>
      <origin 
        xyz="-9.66635791618542E-05 0.000876064475651083 -0.00496880904640868" 
        rpy="0 0 0" />
      <mass 
        value="0.38" />
      <inertia 
        ixx="0.00018501" 
        ixy="0.00000054" 
        ixz="0.00000120" 
        iyy="0.00018965" 
        iyz="-0.00000841" 
        izz="0.00015484" />
    </inertial>
    <visual>
      <origin
        xyz="0 0 0"
        rpy="-1.5707963267948966 0 0" />
      <geometry>
        <mesh
          filename="../meshes/piper/link4.STL" />
      </geometry>
      <material
        name="">
        <color
          rgba="0.792156862745098 0.819607843137255 0.933333333333333 1" />
      </material>
    </visual>
    <collision>
      <origin
        xyz="0 0 0"
        rpy="0 0 0" />
      <geometry>
        <mesh
          filename="../meshes/piper/link4.STL" />
      </geometry>
    </collision>
  </link>
  <joint
    name="joint4"
    type="revolute">
    <origin
      xyz="-0.021984 -0.25075 0"
      rpy="1.5708 0 0" />
    <parent
      link="link3" />
    <child
      link="link4" />
    <axis
      xyz="0 0 1" />
    <limit
      lower="-1.745"
      upper="1.745"
      effort="100"
      velocity="5" />
  </joint>
  <link
    name="link5">
    <inertial>
      <origin 
        xyz="-4.10554118924211E-05 -0.0566486692356075 -0.0037205791677906" 
        rpy="0 0 0" />
      <mass 
        value="0.383" />
      <inertia 
        ixx="0.00166169" 
        ixy="0.00000006" 
        ixz="-0.00000007" 
        iyy="0.00018510" 
        iyz="0.00001026" 
        izz="0.00164321" />
    </inertial>
    <visual>
      <origin
        xyz="0 0 0"
        rpy="-1.5707963267948966 0 0" />
      <geometry>
        <mesh
          filename="../meshes/piper/link5.STL" />
      </geometry>
      <material
        name="">
        <color
          rgba="0.792156862745098 0.819607843137255 0.933333333333333 1" />
      </material>
    </visual>
    <collision>
      <origin
        xyz="0 0 0"
        rpy="0 0 0" />
      <geometry>
        <mesh
          filename="../meshes/piper/link5.STL" />
      </geometry>
    </collision>
  </link>
  <joint
    name="joint5"
    type="revolute">
    <origin
      xyz="0 0 0"
      rpy="-1.5708 0 0" />
    <parent
      link="link4" />
    <child
      link="link5" />
    <axis
      xyz="0 0 1" />
    <limit
      lower="-1.22"
      upper="1.22"
      effort="100"
      velocity="5" />
  </joint>
  <link
    name="link6">
    <inertial>
      <origin 
        xyz="-8.82590762930069E-05 9.0598378529832E-06 -0.002" 
        rpy="0 0 0" />
      <mass 
        value="0.007" />
      <inertia 
        ixx="5.73015540542155E-07" 
        ixy="-1.98305403089247E-22" 
        ixz="-7.2791893904596E-23" 
        iyy="5.73015540542155E-07" 
        iyz="-3.4146026640245E-24" 
        izz="1.06738869138926E-06" />
    </inertial>
    <visual>
      <origin
        xyz="0 0 0"
        rpy="-1.5707963267948966 0 0" />
      <geometry>
        <mesh
          filename="../meshes/piper/link6.STL" />
      </geometry>
      <material
        name="">
        <color
          rgba="0.898039215686275 0.917647058823529 0.929411764705882 1" />
      </material>
    </visual>
    <collision>
      <origin
        xyz="0 0 0"
        rpy="0 0 0" />
      <geometry>
        <mesh
          filename="../meshes/piper/link6.STL" />
      </geometry>
    </collision>
  </link>
  <joint
    name="joint6"
    type="revolute">
    <origin
      xyz="8.8259E-05 -0.091 0"
      rpy="1.5708 0 0" />
    <parent
      link="link5" />
    <child
      link="link6" />
    <axis
      xyz="0 0 1" />
    <limit
      lower="-2.0944"
      upper="2.0944"
      effort="100"
      velocity="3" />
  </joint>
  <link
    name="gripper_base">
    <inertial>
      <origin
        xyz="-0.000183807162235591 8.05033155577911E-05 0.0321436689908876"
        rpy="0 0 0" />
      <mass
        value="0.45" />
      <inertia
        ixx="0.00092934"
        ixy="0.00000034"
        ixz="-0.00000738"
        iyy="0.00071447"
        iyz="0.00000005"
        izz="0.00039442" />
    </inertial>
    <visual>
      <origin
        xyz="0 0 0"
        rpy="-1.5707963267948966 0 0" />
      <geometry>
        <mesh
          filename="../meshes/piper/gripper_base.STL" />
      </geometry>
      <material
        name="">
        <color
          rgba="0.792156862745098 0.819607843137255 0.933333333333333 1" />
      </material>
    </visual>
    <collision>
      <origin
        xyz="0 0 0"
        rpy="0 0 0" />
      <geometry>
        <mesh
          filename="../meshes/piper/gripper_base.STL" />
      </geometry>
    </collision>
  </link> 
  <joint
    name="joint6_to_gripper_base"
    type="fixed">
    <origin
      xyz="0 0 0"
      rpy="0 0 0" />
    <parent
      link="link6" />
    <child
      link="gripper_base" />
  </joint>
  <link
    name="link7">
    <inertial>
      <origin
        xyz="0.00065123185041968 -0.0491929869131989 0.00972258769184025"
        rpy="0 0 0" />
      <mass
        value="0.025" />
      <inertia
        ixx="0.00007371"
        ixy="-0.00000113"
        ixz="0.00000021"
        iyy="0.00000781"
        iyz="-0.00001372"
        izz="0.0000747" />
    </inertial>
    <visual>
      <origin
        xyz="0 0 0"
        rpy="-1.5707963267948966 0 0" />
      <geometry>
        <mesh
          filename="../meshes/piper/link7.STL" />
      </geometry>
      <material
        name="">
        <color
          rgba="0.792156862745098 0.819607843137255 0.933333333333333 1" />
      </material>
    </visual>
    <collision>
      <origin
        xyz="0 0 0"
        rpy="0 0 0" />
      <geometry>
        <mesh
          filename="../meshes/piper/link7.STL" />
      </geometry>
    </collision>
  </link>
  <joint
    name="joint7"
    type="fixed" dont_collapse="true">
    <origin
      xyz="0 0 0.1358"
      rpy="1.5708 0 0" />
    <parent
      link="gripper_base" />
    <child
      link="link7" />
    <axis
      xyz="0 0 1" />
    <limit
      lower="0"
      upper="0.035"
      effort="10"
      velocity="1" />
  </joint>
  <link
    name="link8">
    <inertial>
      <origin
        xyz="0.000651231850419722 -0.0491929869131991 0.00972258769184024"
        rpy="0 0 0" />
      <mass
        value="0.025" />
      <inertia
        ixx="0.00007371"
        ixy="-0.00000113"
        ixz="0.00000021"
        iyy="0.00000781"
        iyz="-0.00001372"
        izz="0.0000747" />
    </inertial>
    <visual>
      <origin
        xyz="0 0 0"
        rpy="-1.5707963267948966 0 0" />
      <geometry>
        <mesh
          filename="../meshes/piper/link8.STL" />
      </geometry>
      <material
        name="">
        <color
          rgba="0.792156862745098 0.819607843137255 0.933333333333333 1" />
      </material>
    </visual>
    <collision>
      <origin
        xyz="0 0 0"
        rpy="0 0 0" />
      <geometry>
        <mesh
          filename="../meshes/piper/link8.STL" />
      </geometry>
    </collision>
  </link>
  <joint
    name="joint8"
    type="fixed" dont_collapse="true">
    <origin
      xyz="0 0 0.1358"
      rpy="1.5708 0 -3.1416" />
    <parent
      link="gripper_base" />
    <child
      link="link8" />
    <axis
      xyz="0 0 -1" />
    <limit
      lower="-0.035"
      upper="0"
      effort="10"
      velocity="1" />
  </joint>

</robot>